Setting up a new session...
Traceback (most recent call last):
  File "/home/vla/micromamba/envs/CYCLEGAN/lib/python3.10/site-packages/urllib3/connection.py", line 198, in _new_conn
    sock = connection.create_connection(
  File "/home/vla/micromamba/envs/CYCLEGAN/lib/python3.10/site-packages/urllib3/util/connection.py", line 85, in create_connection
    raise err
  File "/home/vla/micromamba/envs/CYCLEGAN/lib/python3.10/site-packages/urllib3/util/connection.py", line 73, in create_connection
    sock.connect(sa)
ConnectionRefusedError: [Errno 111] Connection refused

The above exception was the direct cause of the following exception:

Traceback (most recent call last):
  File "/home/vla/micromamba/envs/CYCLEGAN/lib/python3.10/site-packages/urllib3/connectionpool.py", line 787, in urlopen
    response = self._make_request(
  File "/home/vla/micromamba/envs/CYCLEGAN/lib/python3.10/site-packages/urllib3/connectionpool.py", line 493, in _make_request
    conn.request(
  File "/home/vla/micromamba/envs/CYCLEGAN/lib/python3.10/site-packages/urllib3/connection.py", line 445, in request
    self.endheaders()
  File "/home/vla/micromamba/envs/CYCLEGAN/lib/python3.10/http/client.py", line 1278, in endheaders
    self._send_output(message_body, encode_chunked=encode_chunked)
  File "/home/vla/micromamba/envs/CYCLEGAN/lib/python3.10/http/client.py", line 1038, in _send_output
    self.send(msg)
  File "/home/vla/micromamba/envs/CYCLEGAN/lib/python3.10/http/client.py", line 976, in send
    self.connect()
  File "/home/vla/micromamba/envs/CYCLEGAN/lib/python3.10/site-packages/urllib3/connection.py", line 276, in connect
    self.sock = self._new_conn()
  File "/home/vla/micromamba/envs/CYCLEGAN/lib/python3.10/site-packages/urllib3/connection.py", line 213, in _new_conn
    raise NewConnectionError(
urllib3.exceptions.NewConnectionError: <urllib3.connection.HTTPConnection object at 0x1489bcb7c3d0>: Failed to establish a new connection: [Errno 111] Connection refused

The above exception was the direct cause of the following exception:

Traceback (most recent call last):
  File "/home/vla/micromamba/envs/CYCLEGAN/lib/python3.10/site-packages/requests/adapters.py", line 667, in send
    resp = conn.urlopen(
  File "/home/vla/micromamba/envs/CYCLEGAN/lib/python3.10/site-packages/urllib3/connectionpool.py", line 841, in urlopen
    retries = retries.increment(
  File "/home/vla/micromamba/envs/CYCLEGAN/lib/python3.10/site-packages/urllib3/util/retry.py", line 519, in increment
    raise MaxRetryError(_pool, url, reason) from reason  # type: ignore[arg-type]
urllib3.exceptions.MaxRetryError: HTTPConnectionPool(host='localhost', port=8097): Max retries exceeded with url: /env/main (Caused by NewConnectionError('<urllib3.connection.HTTPConnection object at 0x1489bcb7c3d0>: Failed to establish a new connection: [Errno 111] Connection refused'))

During handling of the above exception, another exception occurred:

Traceback (most recent call last):
  File "/home/vla/micromamba/envs/CYCLEGAN/lib/python3.10/site-packages/visdom/__init__.py", line 756, in _send
    return self._handle_post(
  File "/home/vla/micromamba/envs/CYCLEGAN/lib/python3.10/site-packages/visdom/__init__.py", line 720, in _handle_post
    r = self.session.post(url, data=data)
  File "/home/vla/micromamba/envs/CYCLEGAN/lib/python3.10/site-packages/requests/sessions.py", line 637, in post
    return self.request("POST", url, data=data, json=json, **kwargs)
  File "/home/vla/micromamba/envs/CYCLEGAN/lib/python3.10/site-packages/requests/sessions.py", line 589, in request
    resp = self.send(prep, **send_kwargs)
  File "/home/vla/micromamba/envs/CYCLEGAN/lib/python3.10/site-packages/requests/sessions.py", line 703, in send
    r = adapter.send(request, **kwargs)
  File "/home/vla/micromamba/envs/CYCLEGAN/lib/python3.10/site-packages/requests/adapters.py", line 700, in send
    raise ConnectionError(e, request=request)
requests.exceptions.ConnectionError: HTTPConnectionPool(host='localhost', port=8097): Max retries exceeded with url: /env/main (Caused by NewConnectionError('<urllib3.connection.HTTPConnection object at 0x1489bcb7c3d0>: Failed to establish a new connection: [Errno 111] Connection refused'))
[Errno 111] Connection refused
Visdom.setup_socket.<locals>.on_close() takes 1 positional argument but 3 were given
/home/vla/micromamba/envs/CYCLEGAN/lib/python3.10/site-packages/torch/optim/lr_scheduler.py:227: UserWarning: Detected call of `lr_scheduler.step()` before `optimizer.step()`. In PyTorch 1.1.0 and later, you should call them in the opposite order: `optimizer.step()` before `lr_scheduler.step()`.  Failure to do this will result in PyTorch skipping the first value of the learning rate schedule. See more details at https://pytorch.org/docs/stable/optim.html#how-to-adjust-learning-rate
  warnings.warn(
----------------- Options ---------------
               batch_size: 1                             
                    beta1: 0.5                           
          checkpoints_dir: ./checkpoints                 
           continue_train: False                         
                crop_size: 256                           
                 dataroot: /scratch/zt1/project/cmsc828/user/vla/datasets/maps	[default: None]
             dataset_mode: unaligned                     
                direction: AtoB                          
              display_env: main                          
             display_freq: 400                           
               display_id: 1                             
            display_ncols: 4                             
             display_port: 8097                          
           display_server: http://localhost              
          display_winsize: 256                           
                    epoch: latest                        
              epoch_count: 1                             
                 gan_mode: lsgan                         
                  gpu_ids: 0                             
                init_gain: 0.02                          
                init_type: normal                        
                 input_nc: 3                             
                  isTrain: True                          	[default: None]
                 lambda_A: 10.0                          
                 lambda_B: 10.0                          
          lambda_identity: 0.5                           
                load_iter: 0                             	[default: 0]
                load_size: 286                           
                       lr: 0.0002                        
           lr_decay_iters: 50                            
                lr_policy: linear                        
         max_dataset_size: inf                           
                    model: cycle_gan                     
                 n_epochs: 1                             	[default: 100]
           n_epochs_decay: 0                             	[default: 100]
               n_layers_D: 3                             
                     name: maps_cyclegan                 	[default: experiment_name]
                      ndf: 64                            
                     netD: basic                         
                     netG: resnet_9blocks                
                      ngf: 64                            
               no_dropout: True                          
                  no_flip: False                         
                  no_html: True                          	[default: False]
                     norm: instance                      
              num_threads: 4                             
                output_nc: 3                             
                    phase: train                         
                pool_size: 50                            
               preprocess: resize_and_crop               
               print_freq: 100                           
             save_by_iter: False                         
          save_epoch_freq: 5                             
         save_latest_freq: 5000                          
           serial_batches: False                         
                   suffix:                               
         update_html_freq: 1000                          
                use_wandb: False                         
                  verbose: False                         
       wandb_project_name: CycleGAN-and-pix2pix          
----------------- End -------------------
dataset [UnalignedDataset] was created
The number of training images = 1096
initialize network with normal
initialize network with normal
initialize network with normal
initialize network with normal
model [CycleGANModel] was created
---------- Networks initialized -------------
[Network G_A] Total number of parameters : 11.378 M
[Network G_B] Total number of parameters : 11.378 M
[Network D_A] Total number of parameters : 2.765 M
[Network D_B] Total number of parameters : 2.765 M
-----------------------------------------------
Exception in user code:
------------------------------------------------------------


Could not connect to Visdom server. 
 Trying to start a server....
Command: /home/vla/micromamba/envs/CYCLEGAN/bin/python -m visdom.server -p 8097 &>/dev/null &
learning rate 0.0002000 -> 0.0000000
-------------------------------------------------------  ------------  ------------  ------------  ------------  ------------  ------------  ------------  ------------  ------------  ------------  ------------  ------------  ------------  ------------  
                                                   Name    Self CPU %      Self CPU   CPU total %     CPU total  CPU time avg     Self CUDA   Self CUDA %    CUDA total  CUDA time avg       CPU Mem  Self CPU Mem      CUDA Mem  Self CUDA Mem    # of Calls  
-------------------------------------------------------  ------------  ------------  ------------  ------------  ------------  ------------  ------------  ------------  ------------  ------------  ------------  ------------  ------------  ------------  
                                          ProfilerStep*         0.00%       0.000us         0.00%       0.000us       0.000us     417.186ms       206.35%     417.186ms     139.062ms           0 b           0 b           0 b           0 b             3  
                                   DataParallel.forward         0.00%       0.000us         0.00%       0.000us       0.000us     160.802ms        79.54%     160.802ms       4.467ms           0 b           0 b           0 b           0 b            36  
                             aten::convolution_backward         5.28%      34.162ms        12.34%      79.769ms     152.814us      85.176ms        42.13%      95.098ms     182.179us           0 b           0 b       3.37 Gb       2.45 Gb           522  
                                aten::cudnn_convolution         2.62%      16.931ms         5.27%      34.044ms      70.049us      36.505ms        18.06%      36.505ms      75.114us           0 b           0 b       1.93 Gb       1.93 Gb           486  
sm80_xmma_fprop_implicit_gemm_tf32f32_tf32f32_f32_nh...         0.00%       0.000us         0.00%       0.000us       0.000us      22.801ms        11.28%      22.801ms      60.321us           0 b           0 b           0 b           0 b           378  
void cudnn::engines_precompiled::nchwToNhwcKernel<fl...         0.00%       0.000us         0.00%       0.000us       0.000us      22.611ms        11.18%      22.611ms       7.835us           0 b           0 b           0 b           0 b          2886  
sm80_xmma_dgrad_implicit_gemm_tf32f32_tf32f32_f32_nh...         0.00%       0.000us         0.00%       0.000us       0.000us      21.862ms        10.81%      21.862ms      63.923us           0 b           0 b           0 b           0 b           342  
_ZN17cutlass__5x_cudnn6KernelINS_4conv6kernel23Impli...         0.00%       0.000us         0.00%       0.000us       0.000us      19.697ms         9.74%      19.697ms      49.740us           0 b           0 b           0 b           0 b           396  
                       aten::native_batch_norm_backward         0.91%       5.906ms         2.43%      15.680ms      33.504us      12.853ms         6.36%      12.853ms      27.464us           0 b           0 b       2.31 Gb           0 b           468  
void at::native::batch_norm_backward_kernel<float, f...         0.00%       0.000us         0.00%       0.000us       0.000us      12.853ms         6.36%      12.853ms      27.464us           0 b           0 b           0 b           0 b           468  
-------------------------------------------------------  ------------  ------------  ------------  ------------  ------------  ------------  ------------  ------------  ------------  ------------  ------------  ------------  ------------  ------------  
Self CPU time total: 646.542ms
Self CUDA time total: 202.171ms

-------------------------------------------------------  ------------  ------------  ------------  ------------  ------------  ------------  ------------  ------------  ------------  ------------  ------------  ------------  ------------  ------------  
                                                   Name    Self CPU %      Self CPU   CPU total %     CPU total  CPU time avg     Self CUDA   Self CUDA %    CUDA total  CUDA time avg       CPU Mem  Self CPU Mem      CUDA Mem  Self CUDA Mem    # of Calls  
-------------------------------------------------------  ------------  ------------  ------------  ------------  ------------  ------------  ------------  ------------  ------------  ------------  ------------  ------------  ------------  ------------  
                                          ProfilerStep*         0.00%       0.000us         0.00%       0.000us       0.000us     375.111ms       173.40%     375.111ms     125.037ms           0 b           0 b           0 b           0 b             3  
                                   DataParallel.forward         0.00%       0.000us         0.00%       0.000us       0.000us     139.661ms        64.56%     139.661ms       3.879ms           0 b           0 b           0 b           0 b            36  
                             aten::convolution_backward         5.11%      30.123ms        12.31%      72.565ms     139.014us      89.490ms        41.37%      99.674ms     190.947us           0 b           0 b       3.54 Gb       2.46 Gb           522  
                                aten::cudnn_convolution         2.74%      16.128ms         4.60%      27.107ms      55.777us      39.557ms        18.29%      39.557ms      81.394us           0 b           0 b       1.94 Gb       1.94 Gb           486  
sm80_xmma_fprop_implicit_gemm_tf32f32_tf32f32_f32_nh...         0.00%       0.000us         0.00%       0.000us       0.000us      24.975ms        11.54%      24.975ms      66.070us           0 b           0 b           0 b           0 b           378  
void cudnn::engines_precompiled::nchwToNhwcKernel<fl...         0.00%       0.000us         0.00%       0.000us       0.000us      23.784ms        10.99%      23.784ms       8.095us           0 b           0 b           0 b           0 b          2938  
sm80_xmma_dgrad_implicit_gemm_tf32f32_tf32f32_f32_nh...         0.00%       0.000us         0.00%       0.000us       0.000us      23.439ms        10.83%      23.439ms      68.135us           0 b           0 b           0 b           0 b           344  
_ZN17cutlass__5x_cudnn6KernelINS_4conv6kernel23Impli...         0.00%       0.000us         0.00%       0.000us       0.000us      20.965ms         9.69%      20.965ms      52.942us           0 b           0 b           0 b           0 b           396  
void at::native::batch_norm_backward_kernel<float, f...         0.00%       0.000us         0.00%       0.000us       0.000us      13.242ms         6.12%      13.242ms      27.878us           0 b           0 b           0 b           0 b           475  
                       aten::native_batch_norm_backward         0.94%       5.547ms         2.47%      14.569ms      31.131us      13.166ms         6.09%      13.166ms      28.133us           0 b           0 b       2.33 Gb           0 b           468  
-------------------------------------------------------  ------------  ------------  ------------  ------------  ------------  ------------  ------------  ------------  ------------  ------------  ------------  ------------  ------------  ------------  
Self CPU time total: 589.442ms
Self CUDA time total: 216.330ms

Traceback (most recent call last):
  File "/home/vla/micromamba/envs/CYCLEGAN/lib/python3.10/site-packages/urllib3/connection.py", line 198, in _new_conn
    sock = connection.create_connection(
  File "/home/vla/micromamba/envs/CYCLEGAN/lib/python3.10/site-packages/urllib3/util/connection.py", line 85, in create_connection
    raise err
  File "/home/vla/micromamba/envs/CYCLEGAN/lib/python3.10/site-packages/urllib3/util/connection.py", line 73, in create_connection
    sock.connect(sa)
ConnectionRefusedError: [Errno 111] Connection refused

The above exception was the direct cause of the following exception:

Traceback (most recent call last):
  File "/home/vla/micromamba/envs/CYCLEGAN/lib/python3.10/site-packages/urllib3/connectionpool.py", line 787, in urlopen
    response = self._make_request(
  File "/home/vla/micromamba/envs/CYCLEGAN/lib/python3.10/site-packages/urllib3/connectionpool.py", line 493, in _make_request
    conn.request(
  File "/home/vla/micromamba/envs/CYCLEGAN/lib/python3.10/site-packages/urllib3/connection.py", line 445, in request
    self.endheaders()
  File "/home/vla/micromamba/envs/CYCLEGAN/lib/python3.10/http/client.py", line 1278, in endheaders
    self._send_output(message_body, encode_chunked=encode_chunked)
  File "/home/vla/micromamba/envs/CYCLEGAN/lib/python3.10/http/client.py", line 1038, in _send_output
    self.send(msg)
  File "/home/vla/micromamba/envs/CYCLEGAN/lib/python3.10/http/client.py", line 976, in send
    self.connect()
  File "/home/vla/micromamba/envs/CYCLEGAN/lib/python3.10/site-packages/urllib3/connection.py", line 276, in connect
    self.sock = self._new_conn()
  File "/home/vla/micromamba/envs/CYCLEGAN/lib/python3.10/site-packages/urllib3/connection.py", line 213, in _new_conn
    raise NewConnectionError(
urllib3.exceptions.NewConnectionError: <urllib3.connection.HTTPConnection object at 0x148921d9a2f0>: Failed to establish a new connection: [Errno 111] Connection refused

The above exception was the direct cause of the following exception:

Traceback (most recent call last):
  File "/home/vla/micromamba/envs/CYCLEGAN/lib/python3.10/site-packages/requests/adapters.py", line 667, in send
    resp = conn.urlopen(
  File "/home/vla/micromamba/envs/CYCLEGAN/lib/python3.10/site-packages/urllib3/connectionpool.py", line 841, in urlopen
    retries = retries.increment(
  File "/home/vla/micromamba/envs/CYCLEGAN/lib/python3.10/site-packages/urllib3/util/retry.py", line 519, in increment
    raise MaxRetryError(_pool, url, reason) from reason  # type: ignore[arg-type]
urllib3.exceptions.MaxRetryError: HTTPConnectionPool(host='localhost', port=8097): Max retries exceeded with url: /events (Caused by NewConnectionError('<urllib3.connection.HTTPConnection object at 0x148921d9a2f0>: Failed to establish a new connection: [Errno 111] Connection refused'))

During handling of the above exception, another exception occurred:

Traceback (most recent call last):
  File "/home/vla/micromamba/envs/CYCLEGAN/lib/python3.10/site-packages/visdom/__init__.py", line 756, in _send
    return self._handle_post(
  File "/home/vla/micromamba/envs/CYCLEGAN/lib/python3.10/site-packages/visdom/__init__.py", line 720, in _handle_post
    r = self.session.post(url, data=data)
  File "/home/vla/micromamba/envs/CYCLEGAN/lib/python3.10/site-packages/requests/sessions.py", line 637, in post
    return self.request("POST", url, data=data, json=json, **kwargs)
  File "/home/vla/micromamba/envs/CYCLEGAN/lib/python3.10/site-packages/requests/sessions.py", line 589, in request
    resp = self.send(prep, **send_kwargs)
  File "/home/vla/micromamba/envs/CYCLEGAN/lib/python3.10/site-packages/requests/sessions.py", line 703, in send
    r = adapter.send(request, **kwargs)
  File "/home/vla/micromamba/envs/CYCLEGAN/lib/python3.10/site-packages/requests/adapters.py", line 700, in send
    raise ConnectionError(e, request=request)
requests.exceptions.ConnectionError: HTTPConnectionPool(host='localhost', port=8097): Max retries exceeded with url: /events (Caused by NewConnectionError('<urllib3.connection.HTTPConnection object at 0x148921d9a2f0>: Failed to establish a new connection: [Errno 111] Connection refused'))
Traceback (most recent call last):
  File "/home/vla/micromamba/envs/CYCLEGAN/lib/python3.10/site-packages/urllib3/connection.py", line 198, in _new_conn
    sock = connection.create_connection(
  File "/home/vla/micromamba/envs/CYCLEGAN/lib/python3.10/site-packages/urllib3/util/connection.py", line 85, in create_connection
    raise err
  File "/home/vla/micromamba/envs/CYCLEGAN/lib/python3.10/site-packages/urllib3/util/connection.py", line 73, in create_connection
    sock.connect(sa)
ConnectionRefusedError: [Errno 111] Connection refused

The above exception was the direct cause of the following exception:

Traceback (most recent call last):
  File "/home/vla/micromamba/envs/CYCLEGAN/lib/python3.10/site-packages/urllib3/connectionpool.py", line 787, in urlopen
    response = self._make_request(
  File "/home/vla/micromamba/envs/CYCLEGAN/lib/python3.10/site-packages/urllib3/connectionpool.py", line 493, in _make_request
    conn.request(
  File "/home/vla/micromamba/envs/CYCLEGAN/lib/python3.10/site-packages/urllib3/connection.py", line 445, in request
    self.endheaders()
  File "/home/vla/micromamba/envs/CYCLEGAN/lib/python3.10/http/client.py", line 1278, in endheaders
    self._send_output(message_body, encode_chunked=encode_chunked)
  File "/home/vla/micromamba/envs/CYCLEGAN/lib/python3.10/http/client.py", line 1038, in _send_output
    self.send(msg)
  File "/home/vla/micromamba/envs/CYCLEGAN/lib/python3.10/http/client.py", line 976, in send
    self.connect()
  File "/home/vla/micromamba/envs/CYCLEGAN/lib/python3.10/site-packages/urllib3/connection.py", line 276, in connect
    self.sock = self._new_conn()
  File "/home/vla/micromamba/envs/CYCLEGAN/lib/python3.10/site-packages/urllib3/connection.py", line 213, in _new_conn
    raise NewConnectionError(
urllib3.exceptions.NewConnectionError: <urllib3.connection.HTTPConnection object at 0x148921d9ae00>: Failed to establish a new connection: [Errno 111] Connection refused

The above exception was the direct cause of the following exception:

Traceback (most recent call last):
  File "/home/vla/micromamba/envs/CYCLEGAN/lib/python3.10/site-packages/requests/adapters.py", line 667, in send
    resp = conn.urlopen(
  File "/home/vla/micromamba/envs/CYCLEGAN/lib/python3.10/site-packages/urllib3/connectionpool.py", line 841, in urlopen
    retries = retries.increment(
  File "/home/vla/micromamba/envs/CYCLEGAN/lib/python3.10/site-packages/urllib3/util/retry.py", line 519, in increment
    raise MaxRetryError(_pool, url, reason) from reason  # type: ignore[arg-type]
urllib3.exceptions.MaxRetryError: HTTPConnectionPool(host='localhost', port=8097): Max retries exceeded with url: /events (Caused by NewConnectionError('<urllib3.connection.HTTPConnection object at 0x148921d9ae00>: Failed to establish a new connection: [Errno 111] Connection refused'))

During handling of the above exception, another exception occurred:

Traceback (most recent call last):
  File "/home/vla/micromamba/envs/CYCLEGAN/lib/python3.10/site-packages/visdom/__init__.py", line 756, in _send
    return self._handle_post(
  File "/home/vla/micromamba/envs/CYCLEGAN/lib/python3.10/site-packages/visdom/__init__.py", line 720, in _handle_post
    r = self.session.post(url, data=data)
  File "/home/vla/micromamba/envs/CYCLEGAN/lib/python3.10/site-packages/requests/sessions.py", line 637, in post
    return self.request("POST", url, data=data, json=json, **kwargs)
  File "/home/vla/micromamba/envs/CYCLEGAN/lib/python3.10/site-packages/requests/sessions.py", line 589, in request
    resp = self.send(prep, **send_kwargs)
  File "/home/vla/micromamba/envs/CYCLEGAN/lib/python3.10/site-packages/requests/sessions.py", line 703, in send
    r = adapter.send(request, **kwargs)
  File "/home/vla/micromamba/envs/CYCLEGAN/lib/python3.10/site-packages/requests/adapters.py", line 700, in send
    raise ConnectionError(e, request=request)
requests.exceptions.ConnectionError: HTTPConnectionPool(host='localhost', port=8097): Max retries exceeded with url: /events (Caused by NewConnectionError('<urllib3.connection.HTTPConnection object at 0x148921d9ae00>: Failed to establish a new connection: [Errno 111] Connection refused'))
Traceback (most recent call last):
  File "/home/vla/micromamba/envs/CYCLEGAN/lib/python3.10/site-packages/urllib3/connection.py", line 198, in _new_conn
    sock = connection.create_connection(
  File "/home/vla/micromamba/envs/CYCLEGAN/lib/python3.10/site-packages/urllib3/util/connection.py", line 85, in create_connection
    raise err
  File "/home/vla/micromamba/envs/CYCLEGAN/lib/python3.10/site-packages/urllib3/util/connection.py", line 73, in create_connection
    sock.connect(sa)
ConnectionRefusedError: [Errno 111] Connection refused

The above exception was the direct cause of the following exception:

Traceback (most recent call last):
  File "/home/vla/micromamba/envs/CYCLEGAN/lib/python3.10/site-packages/urllib3/connectionpool.py", line 787, in urlopen
    response = self._make_request(
  File "/home/vla/micromamba/envs/CYCLEGAN/lib/python3.10/site-packages/urllib3/connectionpool.py", line 493, in _make_request
    conn.request(
  File "/home/vla/micromamba/envs/CYCLEGAN/lib/python3.10/site-packages/urllib3/connection.py", line 445, in request
    self.endheaders()
  File "/home/vla/micromamba/envs/CYCLEGAN/lib/python3.10/http/client.py", line 1278, in endheaders
    self._send_output(message_body, encode_chunked=encode_chunked)
  File "/home/vla/micromamba/envs/CYCLEGAN/lib/python3.10/http/client.py", line 1038, in _send_output
    self.send(msg)
  File "/home/vla/micromamba/envs/CYCLEGAN/lib/python3.10/http/client.py", line 976, in send
    self.connect()
  File "/home/vla/micromamba/envs/CYCLEGAN/lib/python3.10/site-packages/urllib3/connection.py", line 276, in connect
    self.sock = self._new_conn()
  File "/home/vla/micromamba/envs/CYCLEGAN/lib/python3.10/site-packages/urllib3/connection.py", line 213, in _new_conn
    raise NewConnectionError(
urllib3.exceptions.NewConnectionError: <urllib3.connection.HTTPConnection object at 0x148921c199f0>: Failed to establish a new connection: [Errno 111] Connection refused

The above exception was the direct cause of the following exception:

Traceback (most recent call last):
  File "/home/vla/micromamba/envs/CYCLEGAN/lib/python3.10/site-packages/requests/adapters.py", line 667, in send
    resp = conn.urlopen(
  File "/home/vla/micromamba/envs/CYCLEGAN/lib/python3.10/site-packages/urllib3/connectionpool.py", line 841, in urlopen
    retries = retries.increment(
  File "/home/vla/micromamba/envs/CYCLEGAN/lib/python3.10/site-packages/urllib3/util/retry.py", line 519, in increment
    raise MaxRetryError(_pool, url, reason) from reason  # type: ignore[arg-type]
urllib3.exceptions.MaxRetryError: HTTPConnectionPool(host='localhost', port=8097): Max retries exceeded with url: /events (Caused by NewConnectionError('<urllib3.connection.HTTPConnection object at 0x148921c199f0>: Failed to establish a new connection: [Errno 111] Connection refused'))

During handling of the above exception, another exception occurred:

Traceback (most recent call last):
  File "/home/vla/micromamba/envs/CYCLEGAN/lib/python3.10/site-packages/visdom/__init__.py", line 756, in _send
    return self._handle_post(
  File "/home/vla/micromamba/envs/CYCLEGAN/lib/python3.10/site-packages/visdom/__init__.py", line 720, in _handle_post
    r = self.session.post(url, data=data)
  File "/home/vla/micromamba/envs/CYCLEGAN/lib/python3.10/site-packages/requests/sessions.py", line 637, in post
    return self.request("POST", url, data=data, json=json, **kwargs)
  File "/home/vla/micromamba/envs/CYCLEGAN/lib/python3.10/site-packages/requests/sessions.py", line 589, in request
    resp = self.send(prep, **send_kwargs)
  File "/home/vla/micromamba/envs/CYCLEGAN/lib/python3.10/site-packages/requests/sessions.py", line 703, in send
    r = adapter.send(request, **kwargs)
  File "/home/vla/micromamba/envs/CYCLEGAN/lib/python3.10/site-packages/requests/adapters.py", line 700, in send
    raise ConnectionError(e, request=request)
requests.exceptions.ConnectionError: HTTPConnectionPool(host='localhost', port=8097): Max retries exceeded with url: /events (Caused by NewConnectionError('<urllib3.connection.HTTPConnection object at 0x148921c199f0>: Failed to establish a new connection: [Errno 111] Connection refused'))
Traceback (most recent call last):
  File "/home/vla/micromamba/envs/CYCLEGAN/lib/python3.10/site-packages/urllib3/connection.py", line 198, in _new_conn
    sock = connection.create_connection(
  File "/home/vla/micromamba/envs/CYCLEGAN/lib/python3.10/site-packages/urllib3/util/connection.py", line 85, in create_connection
    raise err
  File "/home/vla/micromamba/envs/CYCLEGAN/lib/python3.10/site-packages/urllib3/util/connection.py", line 73, in create_connection
    sock.connect(sa)
ConnectionRefusedError: [Errno 111] Connection refused

The above exception was the direct cause of the following exception:

Traceback (most recent call last):
  File "/home/vla/micromamba/envs/CYCLEGAN/lib/python3.10/site-packages/urllib3/connectionpool.py", line 787, in urlopen
    response = self._make_request(
  File "/home/vla/micromamba/envs/CYCLEGAN/lib/python3.10/site-packages/urllib3/connectionpool.py", line 493, in _make_request
    conn.request(
  File "/home/vla/micromamba/envs/CYCLEGAN/lib/python3.10/site-packages/urllib3/connection.py", line 445, in request
    self.endheaders()
  File "/home/vla/micromamba/envs/CYCLEGAN/lib/python3.10/http/client.py", line 1278, in endheaders
    self._send_output(message_body, encode_chunked=encode_chunked)
  File "/home/vla/micromamba/envs/CYCLEGAN/lib/python3.10/http/client.py", line 1038, in _send_output
    self.send(msg)
  File "/home/vla/micromamba/envs/CYCLEGAN/lib/python3.10/http/client.py", line 976, in send
    self.connect()
  File "/home/vla/micromamba/envs/CYCLEGAN/lib/python3.10/site-packages/urllib3/connection.py", line 276, in connect
    self.sock = self._new_conn()
  File "/home/vla/micromamba/envs/CYCLEGAN/lib/python3.10/site-packages/urllib3/connection.py", line 213, in _new_conn
    raise NewConnectionError(
urllib3.exceptions.NewConnectionError: <urllib3.connection.HTTPConnection object at 0x148921cd13c0>: Failed to establish a new connection: [Errno 111] Connection refused

The above exception was the direct cause of the following exception:

Traceback (most recent call last):
  File "/home/vla/micromamba/envs/CYCLEGAN/lib/python3.10/site-packages/requests/adapters.py", line 667, in send
    resp = conn.urlopen(
  File "/home/vla/micromamba/envs/CYCLEGAN/lib/python3.10/site-packages/urllib3/connectionpool.py", line 841, in urlopen
    retries = retries.increment(
  File "/home/vla/micromamba/envs/CYCLEGAN/lib/python3.10/site-packages/urllib3/util/retry.py", line 519, in increment
    raise MaxRetryError(_pool, url, reason) from reason  # type: ignore[arg-type]
urllib3.exceptions.MaxRetryError: HTTPConnectionPool(host='localhost', port=8097): Max retries exceeded with url: /events (Caused by NewConnectionError('<urllib3.connection.HTTPConnection object at 0x148921cd13c0>: Failed to establish a new connection: [Errno 111] Connection refused'))

During handling of the above exception, another exception occurred:

Traceback (most recent call last):
  File "/home/vla/micromamba/envs/CYCLEGAN/lib/python3.10/site-packages/visdom/__init__.py", line 756, in _send
    return self._handle_post(
  File "/home/vla/micromamba/envs/CYCLEGAN/lib/python3.10/site-packages/visdom/__init__.py", line 720, in _handle_post
    r = self.session.post(url, data=data)
  File "/home/vla/micromamba/envs/CYCLEGAN/lib/python3.10/site-packages/requests/sessions.py", line 637, in post
    return self.request("POST", url, data=data, json=json, **kwargs)
  File "/home/vla/micromamba/envs/CYCLEGAN/lib/python3.10/site-packages/requests/sessions.py", line 589, in request
    resp = self.send(prep, **send_kwargs)
  File "/home/vla/micromamba/envs/CYCLEGAN/lib/python3.10/site-packages/requests/sessions.py", line 703, in send
    r = adapter.send(request, **kwargs)
  File "/home/vla/micromamba/envs/CYCLEGAN/lib/python3.10/site-packages/requests/adapters.py", line 700, in send
    raise ConnectionError(e, request=request)
requests.exceptions.ConnectionError: HTTPConnectionPool(host='localhost', port=8097): Max retries exceeded with url: /events (Caused by NewConnectionError('<urllib3.connection.HTTPConnection object at 0x148921cd13c0>: Failed to establish a new connection: [Errno 111] Connection refused'))
Traceback (most recent call last):
  File "/home/vla/micromamba/envs/CYCLEGAN/lib/python3.10/site-packages/urllib3/connection.py", line 198, in _new_conn
    sock = connection.create_connection(
  File "/home/vla/micromamba/envs/CYCLEGAN/lib/python3.10/site-packages/urllib3/util/connection.py", line 85, in create_connection
    raise err
  File "/home/vla/micromamba/envs/CYCLEGAN/lib/python3.10/site-packages/urllib3/util/connection.py", line 73, in create_connection
    sock.connect(sa)
ConnectionRefusedError: [Errno 111] Connection refused

The above exception was the direct cause of the following exception:

Traceback (most recent call last):
  File "/home/vla/micromamba/envs/CYCLEGAN/lib/python3.10/site-packages/urllib3/connectionpool.py", line 787, in urlopen
    response = self._make_request(
  File "/home/vla/micromamba/envs/CYCLEGAN/lib/python3.10/site-packages/urllib3/connectionpool.py", line 493, in _make_request
    conn.request(
  File "/home/vla/micromamba/envs/CYCLEGAN/lib/python3.10/site-packages/urllib3/connection.py", line 445, in request
    self.endheaders()
  File "/home/vla/micromamba/envs/CYCLEGAN/lib/python3.10/http/client.py", line 1278, in endheaders
    self._send_output(message_body, encode_chunked=encode_chunked)
  File "/home/vla/micromamba/envs/CYCLEGAN/lib/python3.10/http/client.py", line 1038, in _send_output
    self.send(msg)
  File "/home/vla/micromamba/envs/CYCLEGAN/lib/python3.10/http/client.py", line 976, in send
    self.connect()
  File "/home/vla/micromamba/envs/CYCLEGAN/lib/python3.10/site-packages/urllib3/connection.py", line 276, in connect
    self.sock = self._new_conn()
  File "/home/vla/micromamba/envs/CYCLEGAN/lib/python3.10/site-packages/urllib3/connection.py", line 213, in _new_conn
    raise NewConnectionError(
urllib3.exceptions.NewConnectionError: <urllib3.connection.HTTPConnection object at 0x1488fdad6c80>: Failed to establish a new connection: [Errno 111] Connection refused

The above exception was the direct cause of the following exception:

Traceback (most recent call last):
  File "/home/vla/micromamba/envs/CYCLEGAN/lib/python3.10/site-packages/requests/adapters.py", line 667, in send
    resp = conn.urlopen(
  File "/home/vla/micromamba/envs/CYCLEGAN/lib/python3.10/site-packages/urllib3/connectionpool.py", line 841, in urlopen
    retries = retries.increment(
  File "/home/vla/micromamba/envs/CYCLEGAN/lib/python3.10/site-packages/urllib3/util/retry.py", line 519, in increment
    raise MaxRetryError(_pool, url, reason) from reason  # type: ignore[arg-type]
urllib3.exceptions.MaxRetryError: HTTPConnectionPool(host='localhost', port=8097): Max retries exceeded with url: /events (Caused by NewConnectionError('<urllib3.connection.HTTPConnection object at 0x1488fdad6c80>: Failed to establish a new connection: [Errno 111] Connection refused'))

During handling of the above exception, another exception occurred:

Traceback (most recent call last):
  File "/home/vla/micromamba/envs/CYCLEGAN/lib/python3.10/site-packages/visdom/__init__.py", line 756, in _send
    return self._handle_post(
  File "/home/vla/micromamba/envs/CYCLEGAN/lib/python3.10/site-packages/visdom/__init__.py", line 720, in _handle_post
    r = self.session.post(url, data=data)
  File "/home/vla/micromamba/envs/CYCLEGAN/lib/python3.10/site-packages/requests/sessions.py", line 637, in post
    return self.request("POST", url, data=data, json=json, **kwargs)
  File "/home/vla/micromamba/envs/CYCLEGAN/lib/python3.10/site-packages/requests/sessions.py", line 589, in request
    resp = self.send(prep, **send_kwargs)
  File "/home/vla/micromamba/envs/CYCLEGAN/lib/python3.10/site-packages/requests/sessions.py", line 703, in send
    r = adapter.send(request, **kwargs)
  File "/home/vla/micromamba/envs/CYCLEGAN/lib/python3.10/site-packages/requests/adapters.py", line 700, in send
    raise ConnectionError(e, request=request)
requests.exceptions.ConnectionError: HTTPConnectionPool(host='localhost', port=8097): Max retries exceeded with url: /events (Caused by NewConnectionError('<urllib3.connection.HTTPConnection object at 0x1488fdad6c80>: Failed to establish a new connection: [Errno 111] Connection refused'))
Traceback (most recent call last):
  File "/home/vla/micromamba/envs/CYCLEGAN/lib/python3.10/site-packages/urllib3/connection.py", line 198, in _new_conn
    sock = connection.create_connection(
  File "/home/vla/micromamba/envs/CYCLEGAN/lib/python3.10/site-packages/urllib3/util/connection.py", line 85, in create_connection
    raise err
  File "/home/vla/micromamba/envs/CYCLEGAN/lib/python3.10/site-packages/urllib3/util/connection.py", line 73, in create_connection
    sock.connect(sa)
ConnectionRefusedError: [Errno 111] Connection refused

The above exception was the direct cause of the following exception:

Traceback (most recent call last):
  File "/home/vla/micromamba/envs/CYCLEGAN/lib/python3.10/site-packages/urllib3/connectionpool.py", line 787, in urlopen
    response = self._make_request(
  File "/home/vla/micromamba/envs/CYCLEGAN/lib/python3.10/site-packages/urllib3/connectionpool.py", line 493, in _make_request
    conn.request(
  File "/home/vla/micromamba/envs/CYCLEGAN/lib/python3.10/site-packages/urllib3/connection.py", line 445, in request
    self.endheaders()
  File "/home/vla/micromamba/envs/CYCLEGAN/lib/python3.10/http/client.py", line 1278, in endheaders
    self._send_output(message_body, encode_chunked=encode_chunked)
  File "/home/vla/micromamba/envs/CYCLEGAN/lib/python3.10/http/client.py", line 1038, in _send_output
    self.send(msg)
  File "/home/vla/micromamba/envs/CYCLEGAN/lib/python3.10/http/client.py", line 976, in send
    self.connect()
  File "/home/vla/micromamba/envs/CYCLEGAN/lib/python3.10/site-packages/urllib3/connection.py", line 276, in connect
    self.sock = self._new_conn()
  File "/home/vla/micromamba/envs/CYCLEGAN/lib/python3.10/site-packages/urllib3/connection.py", line 213, in _new_conn
    raise NewConnectionError(
urllib3.exceptions.NewConnectionError: <urllib3.connection.HTTPConnection object at 0x1488fdad67a0>: Failed to establish a new connection: [Errno 111] Connection refused

The above exception was the direct cause of the following exception:

Traceback (most recent call last):
  File "/home/vla/micromamba/envs/CYCLEGAN/lib/python3.10/site-packages/requests/adapters.py", line 667, in send
    resp = conn.urlopen(
  File "/home/vla/micromamba/envs/CYCLEGAN/lib/python3.10/site-packages/urllib3/connectionpool.py", line 841, in urlopen
    retries = retries.increment(
  File "/home/vla/micromamba/envs/CYCLEGAN/lib/python3.10/site-packages/urllib3/util/retry.py", line 519, in increment
    raise MaxRetryError(_pool, url, reason) from reason  # type: ignore[arg-type]
urllib3.exceptions.MaxRetryError: HTTPConnectionPool(host='localhost', port=8097): Max retries exceeded with url: /events (Caused by NewConnectionError('<urllib3.connection.HTTPConnection object at 0x1488fdad67a0>: Failed to establish a new connection: [Errno 111] Connection refused'))

During handling of the above exception, another exception occurred:

Traceback (most recent call last):
  File "/home/vla/micromamba/envs/CYCLEGAN/lib/python3.10/site-packages/visdom/__init__.py", line 756, in _send
    return self._handle_post(
  File "/home/vla/micromamba/envs/CYCLEGAN/lib/python3.10/site-packages/visdom/__init__.py", line 720, in _handle_post
    r = self.session.post(url, data=data)
  File "/home/vla/micromamba/envs/CYCLEGAN/lib/python3.10/site-packages/requests/sessions.py", line 637, in post
    return self.request("POST", url, data=data, json=json, **kwargs)
  File "/home/vla/micromamba/envs/CYCLEGAN/lib/python3.10/site-packages/requests/sessions.py", line 589, in request
    resp = self.send(prep, **send_kwargs)
  File "/home/vla/micromamba/envs/CYCLEGAN/lib/python3.10/site-packages/requests/sessions.py", line 703, in send
    r = adapter.send(request, **kwargs)
  File "/home/vla/micromamba/envs/CYCLEGAN/lib/python3.10/site-packages/requests/adapters.py", line 700, in send
    raise ConnectionError(e, request=request)
requests.exceptions.ConnectionError: HTTPConnectionPool(host='localhost', port=8097): Max retries exceeded with url: /events (Caused by NewConnectionError('<urllib3.connection.HTTPConnection object at 0x1488fdad67a0>: Failed to establish a new connection: [Errno 111] Connection refused'))
Traceback (most recent call last):
  File "/home/vla/micromamba/envs/CYCLEGAN/lib/python3.10/site-packages/urllib3/connection.py", line 198, in _new_conn
    sock = connection.create_connection(
  File "/home/vla/micromamba/envs/CYCLEGAN/lib/python3.10/site-packages/urllib3/util/connection.py", line 85, in create_connection
    raise err
  File "/home/vla/micromamba/envs/CYCLEGAN/lib/python3.10/site-packages/urllib3/util/connection.py", line 73, in create_connection
    sock.connect(sa)
ConnectionRefusedError: [Errno 111] Connection refused

The above exception was the direct cause of the following exception:

Traceback (most recent call last):
  File "/home/vla/micromamba/envs/CYCLEGAN/lib/python3.10/site-packages/urllib3/connectionpool.py", line 787, in urlopen
    response = self._make_request(
  File "/home/vla/micromamba/envs/CYCLEGAN/lib/python3.10/site-packages/urllib3/connectionpool.py", line 493, in _make_request
    conn.request(
  File "/home/vla/micromamba/envs/CYCLEGAN/lib/python3.10/site-packages/urllib3/connection.py", line 445, in request
    self.endheaders()
  File "/home/vla/micromamba/envs/CYCLEGAN/lib/python3.10/http/client.py", line 1278, in endheaders
    self._send_output(message_body, encode_chunked=encode_chunked)
  File "/home/vla/micromamba/envs/CYCLEGAN/lib/python3.10/http/client.py", line 1038, in _send_output
    self.send(msg)
  File "/home/vla/micromamba/envs/CYCLEGAN/lib/python3.10/http/client.py", line 976, in send
    self.connect()
  File "/home/vla/micromamba/envs/CYCLEGAN/lib/python3.10/site-packages/urllib3/connection.py", line 276, in connect
    self.sock = self._new_conn()
  File "/home/vla/micromamba/envs/CYCLEGAN/lib/python3.10/site-packages/urllib3/connection.py", line 213, in _new_conn
    raise NewConnectionError(
urllib3.exceptions.NewConnectionError: <urllib3.connection.HTTPConnection object at 0x1488fdbfd3f0>: Failed to establish a new connection: [Errno 111] Connection refused

The above exception was the direct cause of the following exception:

Traceback (most recent call last):
  File "/home/vla/micromamba/envs/CYCLEGAN/lib/python3.10/site-packages/requests/adapters.py", line 667, in send
    resp = conn.urlopen(
  File "/home/vla/micromamba/envs/CYCLEGAN/lib/python3.10/site-packages/urllib3/connectionpool.py", line 841, in urlopen
    retries = retries.increment(
  File "/home/vla/micromamba/envs/CYCLEGAN/lib/python3.10/site-packages/urllib3/util/retry.py", line 519, in increment
    raise MaxRetryError(_pool, url, reason) from reason  # type: ignore[arg-type]
urllib3.exceptions.MaxRetryError: HTTPConnectionPool(host='localhost', port=8097): Max retries exceeded with url: /events (Caused by NewConnectionError('<urllib3.connection.HTTPConnection object at 0x1488fdbfd3f0>: Failed to establish a new connection: [Errno 111] Connection refused'))

During handling of the above exception, another exception occurred:

Traceback (most recent call last):
  File "/home/vla/micromamba/envs/CYCLEGAN/lib/python3.10/site-packages/visdom/__init__.py", line 756, in _send
    return self._handle_post(
  File "/home/vla/micromamba/envs/CYCLEGAN/lib/python3.10/site-packages/visdom/__init__.py", line 720, in _handle_post
    r = self.session.post(url, data=data)
  File "/home/vla/micromamba/envs/CYCLEGAN/lib/python3.10/site-packages/requests/sessions.py", line 637, in post
    return self.request("POST", url, data=data, json=json, **kwargs)
  File "/home/vla/micromamba/envs/CYCLEGAN/lib/python3.10/site-packages/requests/sessions.py", line 589, in request
    resp = self.send(prep, **send_kwargs)
  File "/home/vla/micromamba/envs/CYCLEGAN/lib/python3.10/site-packages/requests/sessions.py", line 703, in send
    r = adapter.send(request, **kwargs)
  File "/home/vla/micromamba/envs/CYCLEGAN/lib/python3.10/site-packages/requests/adapters.py", line 700, in send
    raise ConnectionError(e, request=request)
requests.exceptions.ConnectionError: HTTPConnectionPool(host='localhost', port=8097): Max retries exceeded with url: /events (Caused by NewConnectionError('<urllib3.connection.HTTPConnection object at 0x1488fdbfd3f0>: Failed to establish a new connection: [Errno 111] Connection refused'))
Traceback (most recent call last):
  File "/home/vla/micromamba/envs/CYCLEGAN/lib/python3.10/site-packages/urllib3/connection.py", line 198, in _new_conn
    sock = connection.create_connection(
  File "/home/vla/micromamba/envs/CYCLEGAN/lib/python3.10/site-packages/urllib3/util/connection.py", line 85, in create_connection
    raise err
  File "/home/vla/micromamba/envs/CYCLEGAN/lib/python3.10/site-packages/urllib3/util/connection.py", line 73, in create_connection
    sock.connect(sa)
ConnectionRefusedError: [Errno 111] Connection refused

The above exception was the direct cause of the following exception:

Traceback (most recent call last):
  File "/home/vla/micromamba/envs/CYCLEGAN/lib/python3.10/site-packages/urllib3/connectionpool.py", line 787, in urlopen
    response = self._make_request(
  File "/home/vla/micromamba/envs/CYCLEGAN/lib/python3.10/site-packages/urllib3/connectionpool.py", line 493, in _make_request
    conn.request(
  File "/home/vla/micromamba/envs/CYCLEGAN/lib/python3.10/site-packages/urllib3/connection.py", line 445, in request
    self.endheaders()
  File "/home/vla/micromamba/envs/CYCLEGAN/lib/python3.10/http/client.py", line 1278, in endheaders
    self._send_output(message_body, encode_chunked=encode_chunked)
  File "/home/vla/micromamba/envs/CYCLEGAN/lib/python3.10/http/client.py", line 1038, in _send_output
    self.send(msg)
  File "/home/vla/micromamba/envs/CYCLEGAN/lib/python3.10/http/client.py", line 976, in send
    self.connect()
  File "/home/vla/micromamba/envs/CYCLEGAN/lib/python3.10/site-packages/urllib3/connection.py", line 276, in connect
    self.sock = self._new_conn()
  File "/home/vla/micromamba/envs/CYCLEGAN/lib/python3.10/site-packages/urllib3/connection.py", line 213, in _new_conn
    raise NewConnectionError(
urllib3.exceptions.NewConnectionError: <urllib3.connection.HTTPConnection object at 0x1488fda270a0>: Failed to establish a new connection: [Errno 111] Connection refused

The above exception was the direct cause of the following exception:

Traceback (most recent call last):
  File "/home/vla/micromamba/envs/CYCLEGAN/lib/python3.10/site-packages/requests/adapters.py", line 667, in send
    resp = conn.urlopen(
  File "/home/vla/micromamba/envs/CYCLEGAN/lib/python3.10/site-packages/urllib3/connectionpool.py", line 841, in urlopen
    retries = retries.increment(
  File "/home/vla/micromamba/envs/CYCLEGAN/lib/python3.10/site-packages/urllib3/util/retry.py", line 519, in increment
    raise MaxRetryError(_pool, url, reason) from reason  # type: ignore[arg-type]
urllib3.exceptions.MaxRetryError: HTTPConnectionPool(host='localhost', port=8097): Max retries exceeded with url: /events (Caused by NewConnectionError('<urllib3.connection.HTTPConnection object at 0x1488fda270a0>: Failed to establish a new connection: [Errno 111] Connection refused'))

During handling of the above exception, another exception occurred:

Traceback (most recent call last):
  File "/home/vla/micromamba/envs/CYCLEGAN/lib/python3.10/site-packages/visdom/__init__.py", line 756, in _send
    return self._handle_post(
  File "/home/vla/micromamba/envs/CYCLEGAN/lib/python3.10/site-packages/visdom/__init__.py", line 720, in _handle_post
    r = self.session.post(url, data=data)
  File "/home/vla/micromamba/envs/CYCLEGAN/lib/python3.10/site-packages/requests/sessions.py", line 637, in post
    return self.request("POST", url, data=data, json=json, **kwargs)
  File "/home/vla/micromamba/envs/CYCLEGAN/lib/python3.10/site-packages/requests/sessions.py", line 589, in request
    resp = self.send(prep, **send_kwargs)
  File "/home/vla/micromamba/envs/CYCLEGAN/lib/python3.10/site-packages/requests/sessions.py", line 703, in send
    r = adapter.send(request, **kwargs)
  File "/home/vla/micromamba/envs/CYCLEGAN/lib/python3.10/site-packages/requests/adapters.py", line 700, in send
    raise ConnectionError(e, request=request)
requests.exceptions.ConnectionError: HTTPConnectionPool(host='localhost', port=8097): Max retries exceeded with url: /events (Caused by NewConnectionError('<urllib3.connection.HTTPConnection object at 0x1488fda270a0>: Failed to establish a new connection: [Errno 111] Connection refused'))
Traceback (most recent call last):
  File "/home/vla/micromamba/envs/CYCLEGAN/lib/python3.10/site-packages/urllib3/connection.py", line 198, in _new_conn
    sock = connection.create_connection(
  File "/home/vla/micromamba/envs/CYCLEGAN/lib/python3.10/site-packages/urllib3/util/connection.py", line 85, in create_connection
    raise err
  File "/home/vla/micromamba/envs/CYCLEGAN/lib/python3.10/site-packages/urllib3/util/connection.py", line 73, in create_connection
    sock.connect(sa)
ConnectionRefusedError: [Errno 111] Connection refused

The above exception was the direct cause of the following exception:

Traceback (most recent call last):
  File "/home/vla/micromamba/envs/CYCLEGAN/lib/python3.10/site-packages/urllib3/connectionpool.py", line 787, in urlopen
    response = self._make_request(
  File "/home/vla/micromamba/envs/CYCLEGAN/lib/python3.10/site-packages/urllib3/connectionpool.py", line 493, in _make_request
    conn.request(
  File "/home/vla/micromamba/envs/CYCLEGAN/lib/python3.10/site-packages/urllib3/connection.py", line 445, in request
    self.endheaders()
  File "/home/vla/micromamba/envs/CYCLEGAN/lib/python3.10/http/client.py", line 1278, in endheaders
    self._send_output(message_body, encode_chunked=encode_chunked)
  File "/home/vla/micromamba/envs/CYCLEGAN/lib/python3.10/http/client.py", line 1038, in _send_output
    self.send(msg)
  File "/home/vla/micromamba/envs/CYCLEGAN/lib/python3.10/http/client.py", line 976, in send
    self.connect()
  File "/home/vla/micromamba/envs/CYCLEGAN/lib/python3.10/site-packages/urllib3/connection.py", line 276, in connect
    self.sock = self._new_conn()
  File "/home/vla/micromamba/envs/CYCLEGAN/lib/python3.10/site-packages/urllib3/connection.py", line 213, in _new_conn
    raise NewConnectionError(
urllib3.exceptions.NewConnectionError: <urllib3.connection.HTTPConnection object at 0x148921d9a2c0>: Failed to establish a new connection: [Errno 111] Connection refused

The above exception was the direct cause of the following exception:

Traceback (most recent call last):
  File "/home/vla/micromamba/envs/CYCLEGAN/lib/python3.10/site-packages/requests/adapters.py", line 667, in send
    resp = conn.urlopen(
  File "/home/vla/micromamba/envs/CYCLEGAN/lib/python3.10/site-packages/urllib3/connectionpool.py", line 841, in urlopen
    retries = retries.increment(
  File "/home/vla/micromamba/envs/CYCLEGAN/lib/python3.10/site-packages/urllib3/util/retry.py", line 519, in increment
    raise MaxRetryError(_pool, url, reason) from reason  # type: ignore[arg-type]
urllib3.exceptions.MaxRetryError: HTTPConnectionPool(host='localhost', port=8097): Max retries exceeded with url: /events (Caused by NewConnectionError('<urllib3.connection.HTTPConnection object at 0x148921d9a2c0>: Failed to establish a new connection: [Errno 111] Connection refused'))

During handling of the above exception, another exception occurred:

Traceback (most recent call last):
  File "/home/vla/micromamba/envs/CYCLEGAN/lib/python3.10/site-packages/visdom/__init__.py", line 756, in _send
    return self._handle_post(
  File "/home/vla/micromamba/envs/CYCLEGAN/lib/python3.10/site-packages/visdom/__init__.py", line 720, in _handle_post
    r = self.session.post(url, data=data)
  File "/home/vla/micromamba/envs/CYCLEGAN/lib/python3.10/site-packages/requests/sessions.py", line 637, in post
    return self.request("POST", url, data=data, json=json, **kwargs)
  File "/home/vla/micromamba/envs/CYCLEGAN/lib/python3.10/site-packages/requests/sessions.py", line 589, in request
    resp = self.send(prep, **send_kwargs)
  File "/home/vla/micromamba/envs/CYCLEGAN/lib/python3.10/site-packages/requests/sessions.py", line 703, in send
    r = adapter.send(request, **kwargs)
  File "/home/vla/micromamba/envs/CYCLEGAN/lib/python3.10/site-packages/requests/adapters.py", line 700, in send
    raise ConnectionError(e, request=request)
requests.exceptions.ConnectionError: HTTPConnectionPool(host='localhost', port=8097): Max retries exceeded with url: /events (Caused by NewConnectionError('<urllib3.connection.HTTPConnection object at 0x148921d9a2c0>: Failed to establish a new connection: [Errno 111] Connection refused'))
Traceback (most recent call last):
  File "/home/vla/micromamba/envs/CYCLEGAN/lib/python3.10/site-packages/urllib3/connection.py", line 198, in _new_conn
    sock = connection.create_connection(
  File "/home/vla/micromamba/envs/CYCLEGAN/lib/python3.10/site-packages/urllib3/util/connection.py", line 85, in create_connection
    raise err
  File "/home/vla/micromamba/envs/CYCLEGAN/lib/python3.10/site-packages/urllib3/util/connection.py", line 73, in create_connection
    sock.connect(sa)
ConnectionRefusedError: [Errno 111] Connection refused

The above exception was the direct cause of the following exception:

Traceback (most recent call last):
  File "/home/vla/micromamba/envs/CYCLEGAN/lib/python3.10/site-packages/urllib3/connectionpool.py", line 787, in urlopen
    response = self._make_request(
  File "/home/vla/micromamba/envs/CYCLEGAN/lib/python3.10/site-packages/urllib3/connectionpool.py", line 493, in _make_request
    conn.request(
  File "/home/vla/micromamba/envs/CYCLEGAN/lib/python3.10/site-packages/urllib3/connection.py", line 445, in request
    self.endheaders()
  File "/home/vla/micromamba/envs/CYCLEGAN/lib/python3.10/http/client.py", line 1278, in endheaders
    self._send_output(message_body, encode_chunked=encode_chunked)
  File "/home/vla/micromamba/envs/CYCLEGAN/lib/python3.10/http/client.py", line 1038, in _send_output
    self.send(msg)
  File "/home/vla/micromamba/envs/CYCLEGAN/lib/python3.10/http/client.py", line 976, in send
    self.connect()
  File "/home/vla/micromamba/envs/CYCLEGAN/lib/python3.10/site-packages/urllib3/connection.py", line 276, in connect
    self.sock = self._new_conn()
  File "/home/vla/micromamba/envs/CYCLEGAN/lib/python3.10/site-packages/urllib3/connection.py", line 213, in _new_conn
    raise NewConnectionError(
urllib3.exceptions.NewConnectionError: <urllib3.connection.HTTPConnection object at 0x1488fda26380>: Failed to establish a new connection: [Errno 111] Connection refused

The above exception was the direct cause of the following exception:

Traceback (most recent call last):
  File "/home/vla/micromamba/envs/CYCLEGAN/lib/python3.10/site-packages/requests/adapters.py", line 667, in send
    resp = conn.urlopen(
  File "/home/vla/micromamba/envs/CYCLEGAN/lib/python3.10/site-packages/urllib3/connectionpool.py", line 841, in urlopen
    retries = retries.increment(
  File "/home/vla/micromamba/envs/CYCLEGAN/lib/python3.10/site-packages/urllib3/util/retry.py", line 519, in increment
    raise MaxRetryError(_pool, url, reason) from reason  # type: ignore[arg-type]
urllib3.exceptions.MaxRetryError: HTTPConnectionPool(host='localhost', port=8097): Max retries exceeded with url: /events (Caused by NewConnectionError('<urllib3.connection.HTTPConnection object at 0x1488fda26380>: Failed to establish a new connection: [Errno 111] Connection refused'))

During handling of the above exception, another exception occurred:

Traceback (most recent call last):
  File "/home/vla/micromamba/envs/CYCLEGAN/lib/python3.10/site-packages/visdom/__init__.py", line 756, in _send
    return self._handle_post(
  File "/home/vla/micromamba/envs/CYCLEGAN/lib/python3.10/site-packages/visdom/__init__.py", line 720, in _handle_post
    r = self.session.post(url, data=data)
  File "/home/vla/micromamba/envs/CYCLEGAN/lib/python3.10/site-packages/requests/sessions.py", line 637, in post
    return self.request("POST", url, data=data, json=json, **kwargs)
  File "/home/vla/micromamba/envs/CYCLEGAN/lib/python3.10/site-packages/requests/sessions.py", line 589, in request
    resp = self.send(prep, **send_kwargs)
  File "/home/vla/micromamba/envs/CYCLEGAN/lib/python3.10/site-packages/requests/sessions.py", line 703, in send
    r = adapter.send(request, **kwargs)
  File "/home/vla/micromamba/envs/CYCLEGAN/lib/python3.10/site-packages/requests/adapters.py", line 700, in send
    raise ConnectionError(e, request=request)
requests.exceptions.ConnectionError: HTTPConnectionPool(host='localhost', port=8097): Max retries exceeded with url: /events (Caused by NewConnectionError('<urllib3.connection.HTTPConnection object at 0x1488fda26380>: Failed to establish a new connection: [Errno 111] Connection refused'))
Traceback (most recent call last):
  File "/home/vla/micromamba/envs/CYCLEGAN/lib/python3.10/site-packages/urllib3/connection.py", line 198, in _new_conn
    sock = connection.create_connection(
  File "/home/vla/micromamba/envs/CYCLEGAN/lib/python3.10/site-packages/urllib3/util/connection.py", line 85, in create_connection
    raise err
  File "/home/vla/micromamba/envs/CYCLEGAN/lib/python3.10/site-packages/urllib3/util/connection.py", line 73, in create_connection
    sock.connect(sa)
ConnectionRefusedError: [Errno 111] Connection refused

The above exception was the direct cause of the following exception:

Traceback (most recent call last):
  File "/home/vla/micromamba/envs/CYCLEGAN/lib/python3.10/site-packages/urllib3/connectionpool.py", line 787, in urlopen
    response = self._make_request(
  File "/home/vla/micromamba/envs/CYCLEGAN/lib/python3.10/site-packages/urllib3/connectionpool.py", line 493, in _make_request
    conn.request(
  File "/home/vla/micromamba/envs/CYCLEGAN/lib/python3.10/site-packages/urllib3/connection.py", line 445, in request
    self.endheaders()
  File "/home/vla/micromamba/envs/CYCLEGAN/lib/python3.10/http/client.py", line 1278, in endheaders
    self._send_output(message_body, encode_chunked=encode_chunked)
  File "/home/vla/micromamba/envs/CYCLEGAN/lib/python3.10/http/client.py", line 1038, in _send_output
    self.send(msg)
  File "/home/vla/micromamba/envs/CYCLEGAN/lib/python3.10/http/client.py", line 976, in send
    self.connect()
  File "/home/vla/micromamba/envs/CYCLEGAN/lib/python3.10/site-packages/urllib3/connection.py", line 276, in connect
    self.sock = self._new_conn()
  File "/home/vla/micromamba/envs/CYCLEGAN/lib/python3.10/site-packages/urllib3/connection.py", line 213, in _new_conn
    raise NewConnectionError(
urllib3.exceptions.NewConnectionError: <urllib3.connection.HTTPConnection object at 0x1488fda52560>: Failed to establish a new connection: [Errno 111] Connection refused

The above exception was the direct cause of the following exception:

Traceback (most recent call last):
  File "/home/vla/micromamba/envs/CYCLEGAN/lib/python3.10/site-packages/requests/adapters.py", line 667, in send
    resp = conn.urlopen(
  File "/home/vla/micromamba/envs/CYCLEGAN/lib/python3.10/site-packages/urllib3/connectionpool.py", line 841, in urlopen
    retries = retries.increment(
  File "/home/vla/micromamba/envs/CYCLEGAN/lib/python3.10/site-packages/urllib3/util/retry.py", line 519, in increment
    raise MaxRetryError(_pool, url, reason) from reason  # type: ignore[arg-type]
urllib3.exceptions.MaxRetryError: HTTPConnectionPool(host='localhost', port=8097): Max retries exceeded with url: /events (Caused by NewConnectionError('<urllib3.connection.HTTPConnection object at 0x1488fda52560>: Failed to establish a new connection: [Errno 111] Connection refused'))

During handling of the above exception, another exception occurred:

Traceback (most recent call last):
  File "/home/vla/micromamba/envs/CYCLEGAN/lib/python3.10/site-packages/visdom/__init__.py", line 756, in _send
    return self._handle_post(
  File "/home/vla/micromamba/envs/CYCLEGAN/lib/python3.10/site-packages/visdom/__init__.py", line 720, in _handle_post
    r = self.session.post(url, data=data)
  File "/home/vla/micromamba/envs/CYCLEGAN/lib/python3.10/site-packages/requests/sessions.py", line 637, in post
    return self.request("POST", url, data=data, json=json, **kwargs)
  File "/home/vla/micromamba/envs/CYCLEGAN/lib/python3.10/site-packages/requests/sessions.py", line 589, in request
    resp = self.send(prep, **send_kwargs)
  File "/home/vla/micromamba/envs/CYCLEGAN/lib/python3.10/site-packages/requests/sessions.py", line 703, in send
    r = adapter.send(request, **kwargs)
  File "/home/vla/micromamba/envs/CYCLEGAN/lib/python3.10/site-packages/requests/adapters.py", line 700, in send
    raise ConnectionError(e, request=request)
requests.exceptions.ConnectionError: HTTPConnectionPool(host='localhost', port=8097): Max retries exceeded with url: /events (Caused by NewConnectionError('<urllib3.connection.HTTPConnection object at 0x1488fda52560>: Failed to establish a new connection: [Errno 111] Connection refused'))
Traceback (most recent call last):
  File "/home/vla/micromamba/envs/CYCLEGAN/lib/python3.10/site-packages/urllib3/connection.py", line 198, in _new_conn
    sock = connection.create_connection(
  File "/home/vla/micromamba/envs/CYCLEGAN/lib/python3.10/site-packages/urllib3/util/connection.py", line 85, in create_connection
    raise err
  File "/home/vla/micromamba/envs/CYCLEGAN/lib/python3.10/site-packages/urllib3/util/connection.py", line 73, in create_connection
    sock.connect(sa)
ConnectionRefusedError: [Errno 111] Connection refused

The above exception was the direct cause of the following exception:

Traceback (most recent call last):
  File "/home/vla/micromamba/envs/CYCLEGAN/lib/python3.10/site-packages/urllib3/connectionpool.py", line 787, in urlopen
    response = self._make_request(
  File "/home/vla/micromamba/envs/CYCLEGAN/lib/python3.10/site-packages/urllib3/connectionpool.py", line 493, in _make_request
    conn.request(
  File "/home/vla/micromamba/envs/CYCLEGAN/lib/python3.10/site-packages/urllib3/connection.py", line 445, in request
    self.endheaders()
  File "/home/vla/micromamba/envs/CYCLEGAN/lib/python3.10/http/client.py", line 1278, in endheaders
    self._send_output(message_body, encode_chunked=encode_chunked)
  File "/home/vla/micromamba/envs/CYCLEGAN/lib/python3.10/http/client.py", line 1038, in _send_output
    self.send(msg)
  File "/home/vla/micromamba/envs/CYCLEGAN/lib/python3.10/http/client.py", line 976, in send
    self.connect()
  File "/home/vla/micromamba/envs/CYCLEGAN/lib/python3.10/site-packages/urllib3/connection.py", line 276, in connect
    self.sock = self._new_conn()
  File "/home/vla/micromamba/envs/CYCLEGAN/lib/python3.10/site-packages/urllib3/connection.py", line 213, in _new_conn
    raise NewConnectionError(
urllib3.exceptions.NewConnectionError: <urllib3.connection.HTTPConnection object at 0x1488fda50280>: Failed to establish a new connection: [Errno 111] Connection refused

The above exception was the direct cause of the following exception:

Traceback (most recent call last):
  File "/home/vla/micromamba/envs/CYCLEGAN/lib/python3.10/site-packages/requests/adapters.py", line 667, in send
    resp = conn.urlopen(
  File "/home/vla/micromamba/envs/CYCLEGAN/lib/python3.10/site-packages/urllib3/connectionpool.py", line 841, in urlopen
    retries = retries.increment(
  File "/home/vla/micromamba/envs/CYCLEGAN/lib/python3.10/site-packages/urllib3/util/retry.py", line 519, in increment
    raise MaxRetryError(_pool, url, reason) from reason  # type: ignore[arg-type]
urllib3.exceptions.MaxRetryError: HTTPConnectionPool(host='localhost', port=8097): Max retries exceeded with url: /events (Caused by NewConnectionError('<urllib3.connection.HTTPConnection object at 0x1488fda50280>: Failed to establish a new connection: [Errno 111] Connection refused'))

During handling of the above exception, another exception occurred:

Traceback (most recent call last):
  File "/home/vla/micromamba/envs/CYCLEGAN/lib/python3.10/site-packages/visdom/__init__.py", line 756, in _send
    return self._handle_post(
  File "/home/vla/micromamba/envs/CYCLEGAN/lib/python3.10/site-packages/visdom/__init__.py", line 720, in _handle_post
    r = self.session.post(url, data=data)
  File "/home/vla/micromamba/envs/CYCLEGAN/lib/python3.10/site-packages/requests/sessions.py", line 637, in post
    return self.request("POST", url, data=data, json=json, **kwargs)
  File "/home/vla/micromamba/envs/CYCLEGAN/lib/python3.10/site-packages/requests/sessions.py", line 589, in request
    resp = self.send(prep, **send_kwargs)
  File "/home/vla/micromamba/envs/CYCLEGAN/lib/python3.10/site-packages/requests/sessions.py", line 703, in send
    r = adapter.send(request, **kwargs)
  File "/home/vla/micromamba/envs/CYCLEGAN/lib/python3.10/site-packages/requests/adapters.py", line 700, in send
    raise ConnectionError(e, request=request)
requests.exceptions.ConnectionError: HTTPConnectionPool(host='localhost', port=8097): Max retries exceeded with url: /events (Caused by NewConnectionError('<urllib3.connection.HTTPConnection object at 0x1488fda50280>: Failed to establish a new connection: [Errno 111] Connection refused'))
Traceback (most recent call last):
  File "/home/vla/micromamba/envs/CYCLEGAN/lib/python3.10/site-packages/urllib3/connection.py", line 198, in _new_conn
    sock = connection.create_connection(
  File "/home/vla/micromamba/envs/CYCLEGAN/lib/python3.10/site-packages/urllib3/util/connection.py", line 85, in create_connection
    raise err
  File "/home/vla/micromamba/envs/CYCLEGAN/lib/python3.10/site-packages/urllib3/util/connection.py", line 73, in create_connection
    sock.connect(sa)
ConnectionRefusedError: [Errno 111] Connection refused

The above exception was the direct cause of the following exception:

Traceback (most recent call last):
  File "/home/vla/micromamba/envs/CYCLEGAN/lib/python3.10/site-packages/urllib3/connectionpool.py", line 787, in urlopen
    response = self._make_request(
  File "/home/vla/micromamba/envs/CYCLEGAN/lib/python3.10/site-packages/urllib3/connectionpool.py", line 493, in _make_request
    conn.request(
  File "/home/vla/micromamba/envs/CYCLEGAN/lib/python3.10/site-packages/urllib3/connection.py", line 445, in request
    self.endheaders()
  File "/home/vla/micromamba/envs/CYCLEGAN/lib/python3.10/http/client.py", line 1278, in endheaders
    self._send_output(message_body, encode_chunked=encode_chunked)
  File "/home/vla/micromamba/envs/CYCLEGAN/lib/python3.10/http/client.py", line 1038, in _send_output
    self.send(msg)
  File "/home/vla/micromamba/envs/CYCLEGAN/lib/python3.10/http/client.py", line 976, in send
    self.connect()
  File "/home/vla/micromamba/envs/CYCLEGAN/lib/python3.10/site-packages/urllib3/connection.py", line 276, in connect
    self.sock = self._new_conn()
  File "/home/vla/micromamba/envs/CYCLEGAN/lib/python3.10/site-packages/urllib3/connection.py", line 213, in _new_conn
    raise NewConnectionError(
urllib3.exceptions.NewConnectionError: <urllib3.connection.HTTPConnection object at 0x1488fda50280>: Failed to establish a new connection: [Errno 111] Connection refused

The above exception was the direct cause of the following exception:

Traceback (most recent call last):
  File "/home/vla/micromamba/envs/CYCLEGAN/lib/python3.10/site-packages/requests/adapters.py", line 667, in send
    resp = conn.urlopen(
  File "/home/vla/micromamba/envs/CYCLEGAN/lib/python3.10/site-packages/urllib3/connectionpool.py", line 841, in urlopen
    retries = retries.increment(
  File "/home/vla/micromamba/envs/CYCLEGAN/lib/python3.10/site-packages/urllib3/util/retry.py", line 519, in increment
    raise MaxRetryError(_pool, url, reason) from reason  # type: ignore[arg-type]
urllib3.exceptions.MaxRetryError: HTTPConnectionPool(host='localhost', port=8097): Max retries exceeded with url: /events (Caused by NewConnectionError('<urllib3.connection.HTTPConnection object at 0x1488fda50280>: Failed to establish a new connection: [Errno 111] Connection refused'))

During handling of the above exception, another exception occurred:

Traceback (most recent call last):
  File "/home/vla/micromamba/envs/CYCLEGAN/lib/python3.10/site-packages/visdom/__init__.py", line 756, in _send
    return self._handle_post(
  File "/home/vla/micromamba/envs/CYCLEGAN/lib/python3.10/site-packages/visdom/__init__.py", line 720, in _handle_post
    r = self.session.post(url, data=data)
  File "/home/vla/micromamba/envs/CYCLEGAN/lib/python3.10/site-packages/requests/sessions.py", line 637, in post
    return self.request("POST", url, data=data, json=json, **kwargs)
  File "/home/vla/micromamba/envs/CYCLEGAN/lib/python3.10/site-packages/requests/sessions.py", line 589, in request
    resp = self.send(prep, **send_kwargs)
  File "/home/vla/micromamba/envs/CYCLEGAN/lib/python3.10/site-packages/requests/sessions.py", line 703, in send
    r = adapter.send(request, **kwargs)
  File "/home/vla/micromamba/envs/CYCLEGAN/lib/python3.10/site-packages/requests/adapters.py", line 700, in send
    raise ConnectionError(e, request=request)
requests.exceptions.ConnectionError: HTTPConnectionPool(host='localhost', port=8097): Max retries exceeded with url: /events (Caused by NewConnectionError('<urllib3.connection.HTTPConnection object at 0x1488fda50280>: Failed to establish a new connection: [Errno 111] Connection refused'))
Traceback (most recent call last):
  File "/home/vla/micromamba/envs/CYCLEGAN/lib/python3.10/site-packages/urllib3/connection.py", line 198, in _new_conn
    sock = connection.create_connection(
  File "/home/vla/micromamba/envs/CYCLEGAN/lib/python3.10/site-packages/urllib3/util/connection.py", line 85, in create_connection
    raise err
  File "/home/vla/micromamba/envs/CYCLEGAN/lib/python3.10/site-packages/urllib3/util/connection.py", line 73, in create_connection
    sock.connect(sa)
ConnectionRefusedError: [Errno 111] Connection refused

The above exception was the direct cause of the following exception:

Traceback (most recent call last):
  File "/home/vla/micromamba/envs/CYCLEGAN/lib/python3.10/site-packages/urllib3/connectionpool.py", line 787, in urlopen
    response = self._make_request(
  File "/home/vla/micromamba/envs/CYCLEGAN/lib/python3.10/site-packages/urllib3/connectionpool.py", line 493, in _make_request
    conn.request(
  File "/home/vla/micromamba/envs/CYCLEGAN/lib/python3.10/site-packages/urllib3/connection.py", line 445, in request
    self.endheaders()
  File "/home/vla/micromamba/envs/CYCLEGAN/lib/python3.10/http/client.py", line 1278, in endheaders
    self._send_output(message_body, encode_chunked=encode_chunked)
  File "/home/vla/micromamba/envs/CYCLEGAN/lib/python3.10/http/client.py", line 1038, in _send_output
    self.send(msg)
  File "/home/vla/micromamba/envs/CYCLEGAN/lib/python3.10/http/client.py", line 976, in send
    self.connect()
  File "/home/vla/micromamba/envs/CYCLEGAN/lib/python3.10/site-packages/urllib3/connection.py", line 276, in connect
    self.sock = self._new_conn()
  File "/home/vla/micromamba/envs/CYCLEGAN/lib/python3.10/site-packages/urllib3/connection.py", line 213, in _new_conn
    raise NewConnectionError(
urllib3.exceptions.NewConnectionError: <urllib3.connection.HTTPConnection object at 0x1488fda26830>: Failed to establish a new connection: [Errno 111] Connection refused

The above exception was the direct cause of the following exception:

Traceback (most recent call last):
  File "/home/vla/micromamba/envs/CYCLEGAN/lib/python3.10/site-packages/requests/adapters.py", line 667, in send
    resp = conn.urlopen(
  File "/home/vla/micromamba/envs/CYCLEGAN/lib/python3.10/site-packages/urllib3/connectionpool.py", line 841, in urlopen
    retries = retries.increment(
  File "/home/vla/micromamba/envs/CYCLEGAN/lib/python3.10/site-packages/urllib3/util/retry.py", line 519, in increment
    raise MaxRetryError(_pool, url, reason) from reason  # type: ignore[arg-type]
urllib3.exceptions.MaxRetryError: HTTPConnectionPool(host='localhost', port=8097): Max retries exceeded with url: /events (Caused by NewConnectionError('<urllib3.connection.HTTPConnection object at 0x1488fda26830>: Failed to establish a new connection: [Errno 111] Connection refused'))

During handling of the above exception, another exception occurred:

Traceback (most recent call last):
  File "/home/vla/micromamba/envs/CYCLEGAN/lib/python3.10/site-packages/visdom/__init__.py", line 756, in _send
    return self._handle_post(
  File "/home/vla/micromamba/envs/CYCLEGAN/lib/python3.10/site-packages/visdom/__init__.py", line 720, in _handle_post
    r = self.session.post(url, data=data)
  File "/home/vla/micromamba/envs/CYCLEGAN/lib/python3.10/site-packages/requests/sessions.py", line 637, in post
    return self.request("POST", url, data=data, json=json, **kwargs)
  File "/home/vla/micromamba/envs/CYCLEGAN/lib/python3.10/site-packages/requests/sessions.py", line 589, in request
    resp = self.send(prep, **send_kwargs)
  File "/home/vla/micromamba/envs/CYCLEGAN/lib/python3.10/site-packages/requests/sessions.py", line 703, in send
    r = adapter.send(request, **kwargs)
  File "/home/vla/micromamba/envs/CYCLEGAN/lib/python3.10/site-packages/requests/adapters.py", line 700, in send
    raise ConnectionError(e, request=request)
requests.exceptions.ConnectionError: HTTPConnectionPool(host='localhost', port=8097): Max retries exceeded with url: /events (Caused by NewConnectionError('<urllib3.connection.HTTPConnection object at 0x1488fda26830>: Failed to establish a new connection: [Errno 111] Connection refused'))
-------------------------------------------------------  ------------  ------------  ------------  ------------  ------------  ------------  ------------  ------------  ------------  ------------  ------------  ------------  ------------  ------------  
                                                   Name    Self CPU %      Self CPU   CPU total %     CPU total  CPU time avg     Self CUDA   Self CUDA %    CUDA total  CUDA time avg       CPU Mem  Self CPU Mem      CUDA Mem  Self CUDA Mem    # of Calls  
-------------------------------------------------------  ------------  ------------  ------------  ------------  ------------  ------------  ------------  ------------  ------------  ------------  ------------  ------------  ------------  ------------  
                                          ProfilerStep*         0.00%       0.000us         0.00%       0.000us       0.000us     374.005ms       169.92%     374.005ms     124.668ms           0 b           0 b           0 b           0 b             3  
                                   DataParallel.forward         0.00%       0.000us         0.00%       0.000us       0.000us     140.702ms        63.93%     140.702ms       3.908ms           0 b           0 b           0 b           0 b            36  
                             aten::convolution_backward         5.12%      30.085ms        12.40%      72.815ms     139.493us      92.020ms        41.81%     102.427ms     196.220us           0 b           0 b       3.53 Gb       2.46 Gb           522  
                                aten::cudnn_convolution         2.75%      16.161ms         4.63%      27.208ms      55.983us      39.679ms        18.03%      39.679ms      81.644us           0 b           0 b       1.94 Gb       1.94 Gb           486  
sm80_xmma_fprop_implicit_gemm_tf32f32_tf32f32_f32_nh...         0.00%       0.000us         0.00%       0.000us       0.000us      25.017ms        11.37%      25.017ms      66.182us           0 b           0 b           0 b           0 b           378  
sm80_xmma_dgrad_implicit_gemm_tf32f32_tf32f32_f32_nh...         0.00%       0.000us         0.00%       0.000us       0.000us      24.136ms        10.97%      24.136ms      70.164us           0 b           0 b           0 b           0 b           344  
void cudnn::engines_precompiled::nchwToNhwcKernel<fl...         0.00%       0.000us         0.00%       0.000us       0.000us      24.069ms        10.94%      24.069ms       8.187us           0 b           0 b           0 b           0 b          2940  
_ZN17cutlass__5x_cudnn6KernelINS_4conv6kernel23Impli...         0.00%       0.000us         0.00%       0.000us       0.000us      21.596ms         9.81%      21.596ms      54.536us           0 b           0 b           0 b           0 b           396  
void at::native::batch_norm_backward_kernel<float, f...         0.00%       0.000us         0.00%       0.000us       0.000us      13.543ms         6.15%      13.543ms      28.452us           0 b           0 b           0 b           0 b           476  
                       aten::native_batch_norm_backward         0.94%       5.528ms         2.48%      14.554ms      31.097us      13.461ms         6.12%      13.461ms      28.762us           0 b           0 b       2.33 Gb           0 b           468  
-------------------------------------------------------  ------------  ------------  ------------  ------------  ------------  ------------  ------------  ------------  ------------  ------------  ------------  ------------  ------------  ------------  
Self CPU time total: 587.107ms
Self CUDA time total: 220.101ms

(epoch: 1, iters: 100, time: 0.089, data: 0.670) D_A: 1.939 G_A: 2.567 cycle_A: 8.252 idt_A: 4.691 D_B: 1.587 G_B: 1.785 cycle_B: 9.449 idt_B: 3.972 
Exception in user code:
------------------------------------------------------------
(epoch: 1, iters: 200, time: 0.087, data: 0.001) D_A: 1.942 G_A: 2.628 cycle_A: 7.542 idt_A: 3.928 D_B: 1.626 G_B: 1.747 cycle_B: 8.039 idt_B: 3.720 
Exception in user code:
------------------------------------------------------------
(epoch: 1, iters: 300, time: 0.088, data: 0.001) D_A: 1.914 G_A: 2.612 cycle_A: 7.373 idt_A: 4.393 D_B: 1.598 G_B: 1.705 cycle_B: 8.852 idt_B: 3.680 
Exception in user code:
------------------------------------------------------------
Exception in user code:
------------------------------------------------------------
Exception in user code:
------------------------------------------------------------
(epoch: 1, iters: 400, time: 0.207, data: 0.001) D_A: 1.990 G_A: 2.386 cycle_A: 7.566 idt_A: 4.829 D_B: 1.490 G_B: 1.814 cycle_B: 9.754 idt_B: 3.586 
Exception in user code:
------------------------------------------------------------
(epoch: 1, iters: 500, time: 0.088, data: 0.001) D_A: 1.944 G_A: 2.735 cycle_A: 7.898 idt_A: 4.915 D_B: 1.502 G_B: 1.827 cycle_B: 9.899 idt_B: 3.930 
Exception in user code:
------------------------------------------------------------
(epoch: 1, iters: 600, time: 0.088, data: 0.000) D_A: 2.199 G_A: 2.745 cycle_A: 7.644 idt_A: 4.824 D_B: 1.595 G_B: 1.617 cycle_B: 9.747 idt_B: 3.744 
Exception in user code:
------------------------------------------------------------
(epoch: 1, iters: 700, time: 0.088, data: 0.002) D_A: 1.955 G_A: 2.652 cycle_A: 7.205 idt_A: 4.898 D_B: 1.669 G_B: 1.759 cycle_B: 9.826 idt_B: 3.603 
Exception in user code:
------------------------------------------------------------
Exception in user code:
------------------------------------------------------------
Exception in user code:
------------------------------------------------------------
(epoch: 1, iters: 800, time: 0.191, data: 0.001) D_A: 1.855 G_A: 2.538 cycle_A: 7.130 idt_A: 4.013 D_B: 1.519 G_B: 1.902 cycle_B: 8.152 idt_B: 3.483 
Exception in user code:
------------------------------------------------------------
(epoch: 1, iters: 900, time: 0.088, data: 0.001) D_A: 1.902 G_A: 2.577 cycle_A: 7.264 idt_A: 4.144 D_B: 1.604 G_B: 1.725 cycle_B: 8.438 idt_B: 3.602 
Exception in user code:
------------------------------------------------------------
(epoch: 1, iters: 1000, time: 0.089, data: 0.001) D_A: 2.008 G_A: 2.724 cycle_A: 7.541 idt_A: 3.627 D_B: 1.315 G_B: 1.567 cycle_B: 7.626 idt_B: 3.711 
Exception in user code:
------------------------------------------------------------
End of epoch 1 / 1 	 Time Taken: 124 sec
-------------------------------------------------------  ------------  ------------  ------------  ------------  ------------  ------------  ------------  ------------  ------------  ------------  ------------  ------------  ------------  ------------  
                                                   Name    Self CPU %      Self CPU   CPU total %     CPU total  CPU time avg     Self CUDA   Self CUDA %    CUDA total  CUDA time avg       CPU Mem  Self CPU Mem      CUDA Mem  Self CUDA Mem    # of Calls  
-------------------------------------------------------  ------------  ------------  ------------  ------------  ------------  ------------  ------------  ------------  ------------  ------------  ------------  ------------  ------------  ------------  
                                            aten::empty         2.94%      17.278ms         2.97%      17.429ms       4.640us       0.000us         0.00%       0.000us       0.000us          24 b          24 b       8.34 Gb       8.34 Gb          3756  
                                    aten::empty_strided         0.95%       5.583ms         0.95%       5.583ms       4.910us       0.000us         0.00%       0.000us       0.000us           0 b           0 b       4.30 Gb       4.30 Gb          1137  
                             aten::convolution_backward         5.12%      30.085ms        12.40%      72.815ms     139.493us      92.020ms        41.81%     102.427ms     196.220us           0 b           0 b       3.53 Gb       2.46 Gb           522  
                                aten::cudnn_convolution         2.75%      16.161ms         4.63%      27.208ms      55.983us      39.679ms        18.03%      39.679ms      81.644us           0 b           0 b       1.94 Gb       1.94 Gb           486  
                                          aten::resize_         0.26%       1.500ms         0.26%       1.500ms       3.847us       0.000us         0.00%       0.000us       0.000us           0 b           0 b       1.66 Gb       1.66 Gb           390  
                               aten::threshold_backward         0.42%       2.451ms         0.71%       4.172ms      16.555us       3.219ms         1.46%       3.219ms      12.775us           0 b           0 b       1.58 Gb       1.58 Gb           252  
                                              aten::add         0.35%       2.029ms         0.54%       3.161ms      17.272us       1.183ms         0.54%       1.183ms       6.463us           0 b           0 b     659.44 Mb     659.44 Mb           183  
                      aten::cudnn_convolution_transpose         0.20%       1.151ms         0.35%       2.049ms      56.930us       2.933ms         1.33%       2.933ms      81.477us           0 b           0 b     436.56 Mb     436.56 Mb            36  
                              aten::leaky_relu_backward         0.13%     752.369us         0.29%       1.699ms      23.591us     337.148us         0.15%     337.148us       4.683us           0 b           0 b     160.52 Mb     160.52 Mb            72  
                                             aten::tanh         0.04%     258.260us         0.06%     379.559us      21.087us      56.800us         0.03%      56.800us       3.156us           0 b           0 b      13.50 Mb      13.50 Mb            18  
                                    aten::tanh_backward         0.03%     186.425us         0.05%     308.964us      17.165us      66.558us         0.03%      66.558us       3.698us           0 b           0 b      13.50 Mb      13.50 Mb            18  
                                              aten::mul         0.12%     675.189us         0.24%       1.419ms      23.653us     135.836us         0.06%     135.836us       2.264us           0 b           0 b       9.02 Mb       9.02 Mb            60  
                                              aten::sub         0.03%     179.110us         0.05%     279.852us      23.321us      43.808us         0.02%      43.808us       3.651us           0 b           0 b       9.00 Mb       9.00 Mb            12  
                                              aten::div         0.04%     220.115us         0.06%     325.086us      27.090us      44.254us         0.02%      44.254us       3.688us           0 b           0 b       9.00 Mb       9.00 Mb            12  
                                              aten::sgn         0.02%     143.855us         0.04%     228.983us      19.082us      37.118us         0.02%      37.118us       3.093us           0 b           0 b       9.00 Mb       9.00 Mb            12  
                                              aten::cat         0.03%     164.329us         0.05%     316.126us      52.688us      21.087us         0.01%      21.087us       3.514us           0 b           0 b       4.50 Mb       4.50 Mb             6  
                                           Buffer Flush         0.10%     584.835us         0.10%     584.835us     194.945us      16.320us         0.01%      16.320us       5.440us           0 b           0 b       4.00 Mb       4.00 Mb             3  
                                              aten::sum         1.36%       7.991ms         2.01%      11.792ms      23.968us      10.406ms         4.73%      10.406ms      21.151us           0 b           0 b     441.00 Kb     441.00 Kb           492  
                                             aten::mean         0.08%     446.427us         0.12%     723.728us      24.124us     193.695us         0.09%     193.695us       6.457us           0 b           0 b       6.00 Kb       6.00 Kb            30  
void at::native::vectorized_elementwise_kernel<4, at...         0.00%       0.000us         0.00%       0.000us       0.000us       4.880ms         2.22%       4.880ms       4.798us           0 b           0 b           0 b           0 b          1017  
void at::native::vectorized_elementwise_kernel<4, at...         0.00%       0.000us         0.00%       0.000us       0.000us       2.894ms         1.31%       2.894ms       4.182us           0 b           0 b           0 b           0 b           692  
                         Memcpy DtoD (Device -> Device)         0.00%       0.000us         0.00%       0.000us       0.000us      10.045ms         4.56%      10.045ms       7.878us           0 b           0 b           0 b           0 b          1275  
void at::native::vectorized_elementwise_kernel<4, at...         0.00%       0.000us         0.00%       0.000us       0.000us     394.588us         0.18%     394.588us       4.754us           0 b           0 b           0 b           0 b            83  
void at::native::batch_norm_backward_kernel<float, f...         0.00%       0.000us         0.00%       0.000us       0.000us      13.543ms         6.15%      13.543ms      28.452us           0 b           0 b           0 b           0 b           476  
void cudnn::engines_precompiled::nchwToNhwcKernel<fl...         0.00%       0.000us         0.00%       0.000us       0.000us      24.069ms        10.94%      24.069ms       8.187us           0 b           0 b           0 b           0 b          2940  
void cutlass__5x_cudnn::Kernel<cutlass_tensorop_s168...         0.00%       0.000us         0.00%       0.000us       0.000us       2.151ms         0.98%       2.151ms      37.730us           0 b           0 b           0 b           0 b            57  
enumerate(DataLoader)#_MultiProcessingDataLoaderIter...         0.39%       2.302ms         0.40%       2.339ms     779.503us       0.000us         0.00%       0.000us       0.000us       4.50 Mb       4.50 Mb           0 b           0 b             3  
void cudnn::engines_precompiled::nhwcToNchwKernel<fl...         0.00%       0.000us         0.00%       0.000us       0.000us       7.708ms         3.50%       7.708ms       7.117us           0 b           0 b           0 b           0 b          1083  
                                        Memset (Device)         0.00%       0.000us         0.00%       0.000us       0.000us       2.714ms         1.23%       2.714ms       4.221us           0 b           0 b           0 b           0 b           643  
void cutlass__5x_cudnn::Kernel<cutlass_tensorop_s168...         0.00%       0.000us         0.00%       0.000us       0.000us       1.517ms         0.69%       1.517ms      52.298us           0 b           0 b           0 b           0 b            29  
void at::native::reduce_kernel<512, 1, at::native::R...         0.00%       0.000us         0.00%       0.000us       0.000us      10.544ms         4.79%      10.544ms      20.879us           0 b           0 b           0 b           0 b           505  
void cutlass__5x_cudnn::Kernel<cutlass_tensorop_s168...         0.00%       0.000us         0.00%       0.000us       0.000us       3.012ms         1.37%       3.012ms      52.834us           0 b           0 b           0 b           0 b            57  
sm80_xmma_wgrad_implicit_gemm_indexed_tf32f32_tf32f3...         0.00%       0.000us         0.00%       0.000us       0.000us     723.482us         0.33%     723.482us      48.232us           0 b           0 b           0 b           0 b            15  
_ZN17cutlass__5x_cudnn6KernelINS_4conv6kernel23Impli...         0.00%       0.000us         0.00%       0.000us       0.000us     969.940us         0.44%     969.940us      29.392us           0 b           0 b           0 b           0 b            33  
void cutlass__5x_cudnn::Kernel<cutlass__5x_cudnn::re...         0.00%       0.000us         0.00%       0.000us       0.000us       2.299ms         1.04%       2.299ms       5.359us           0 b           0 b           0 b           0 b           429  
void implicit_convolve_sgemm<float, float, 128, 5, 5...         0.00%       0.000us         0.00%       0.000us       0.000us     414.840us         0.19%     414.840us      20.742us           0 b           0 b           0 b           0 b            20  
void at::native::elementwise_kernel<128, 2, at::nati...         0.00%       0.000us         0.00%       0.000us       0.000us       4.323ms         1.96%       4.323ms       8.126us           0 b           0 b           0 b           0 b           532  
void at::native::vectorized_elementwise_kernel<4, at...         0.00%       0.000us         0.00%       0.000us       0.000us     288.822us         0.13%     288.822us       3.610us           0 b           0 b           0 b           0 b            80  
void cutlass__5x_cudnn::Kernel<cutlass_tensorop_s168...         0.00%       0.000us         0.00%       0.000us       0.000us       1.749ms         0.79%       1.749ms      43.728us           0 b           0 b           0 b           0 b            40  
                                             aten::set_         0.00%      20.030us         0.00%      20.030us       3.338us       0.000us         0.00%       0.000us       0.000us           0 b           0 b           0 b           0 b             6  
void at::native::batch_norm_collect_statistics_kerne...         0.00%       0.000us         0.00%       0.000us       0.000us       5.881ms         2.67%       5.881ms      12.407us           0 b           0 b           0 b           0 b           474  
void at::native::vectorized_elementwise_kernel<4, at...         0.00%       0.000us         0.00%       0.000us       0.000us       1.051ms         0.48%       1.051ms       2.218us           0 b           0 b           0 b           0 b           474  
void at::native::batch_norm_transform_input_kernel<f...         0.00%       0.000us         0.00%       0.000us       0.000us       5.137ms         2.33%       5.137ms      10.838us           0 b           0 b           0 b           0 b           474  
void cutlass__5x_cudnn::Kernel<cutlass_tensorop_s168...         0.00%       0.000us         0.00%       0.000us       0.000us     524.761us         0.24%     524.761us      26.238us           0 b           0 b           0 b           0 b            20  
void tensorTransformGeneric<float, float, float, tru...         0.00%       0.000us         0.00%       0.000us       0.000us       1.026ms         0.47%       1.026ms      17.695us           0 b           0 b           0 b           0 b            58  
sm80_xmma_fprop_implicit_gemm_tf32f32_tf32f32_f32_nh...         0.00%       0.000us         0.00%       0.000us       0.000us     688.087us         0.31%     688.087us      34.404us           0 b           0 b           0 b           0 b            20  
void nchwAddPaddingKernel<float, float, float, true,...         0.00%       0.000us         0.00%       0.000us       0.000us      54.015us         0.02%      54.015us       2.701us           0 b           0 b           0 b           0 b            20  
void at::native::elementwise_kernel<128, 2, at::nati...         0.00%       0.000us         0.00%       0.000us       0.000us      62.624us         0.03%      62.624us       3.131us           0 b           0 b           0 b           0 b            20  
void at::native::reduce_kernel<512, 1, at::native::R...         0.00%       0.000us         0.00%       0.000us       0.000us     191.741us         0.09%     191.741us       5.992us           0 b           0 b           0 b           0 b            32  
void at::native::vectorized_elementwise_kernel<4, at...         0.00%       0.000us         0.00%       0.000us       0.000us     106.269us         0.05%     106.269us       2.125us           0 b           0 b           0 b           0 b            50  
void at::native::elementwise_kernel<128, 2, at::nati...         0.00%       0.000us         0.00%       0.000us       0.000us      67.586us         0.03%      67.586us       3.379us           0 b           0 b           0 b           0 b            20  
void cutlass__5x_cudnn::Kernel<cutlass_tensorop_s168...         0.00%       0.000us         0.00%       0.000us       0.000us       1.808ms         0.82%       1.808ms      47.587us           0 b           0 b           0 b           0 b            38  
void cudnn::cnn::wgrad2d_grouped_direct_kernel<false...         0.00%       0.000us         0.00%       0.000us       0.000us     377.147us         0.17%     377.147us      26.939us           0 b           0 b           0 b           0 b            14  
sm80_xmma_dgrad_implicit_gemm_tf32f32_tf32f32_f32_nh...         0.00%       0.000us         0.00%       0.000us       0.000us      24.136ms        10.97%      24.136ms      70.164us           0 b           0 b           0 b           0 b           344  
                                               aten::to         0.05%     305.941us         0.75%       4.414ms       8.863us       0.000us         0.00%       1.684ms       3.381us           0 b           0 b       4.50 Mb           0 b           498  
                                         aten::_to_copy         0.01%      38.315us         0.70%       4.108ms     684.679us       0.000us         0.00%       1.684ms     280.589us           0 b           0 b       4.50 Mb           0 b             6  
                                            aten::copy_         0.91%       5.357ms         3.38%      19.829ms      15.966us      11.531ms         5.24%      11.531ms       9.284us           0 b           0 b           0 b           0 b          1242  
                                        cudaMemcpyAsync         1.91%      11.229ms         1.91%      11.229ms       8.997us       0.000us         0.00%       0.000us       0.000us           0 b           0 b           0 b           0 b          1248  
                                  cudaStreamSynchronize         0.57%       3.360ms         0.57%       3.360ms     559.921us       0.000us         0.00%       0.000us       0.000us           0 b           0 b           0 b           0 b             6  
void at::native::(anonymous namespace)::multi_tensor...         0.00%       0.000us         0.00%       0.000us       0.000us     850.326us         0.39%     850.326us      85.033us           0 b           0 b           0 b           0 b            10  
void at::native::(anonymous namespace)::multi_tensor...         0.00%       0.000us         0.00%       0.000us       0.000us     623.706us         0.28%     623.706us      62.371us           0 b           0 b           0 b           0 b            10  
void at::native::(anonymous namespace)::multi_tensor...         0.00%       0.000us         0.00%       0.000us       0.000us     880.758us         0.40%     880.758us      88.076us           0 b           0 b           0 b           0 b            10  
void at::native::(anonymous namespace)::multi_tensor...         0.00%       0.000us         0.00%       0.000us       0.000us     636.410us         0.29%     636.410us      63.641us           0 b           0 b           0 b           0 b            10  
void at::native::(anonymous namespace)::multi_tensor...         0.00%       0.000us         0.00%       0.000us       0.000us     607.864us         0.28%     607.864us      60.786us           0 b           0 b           0 b           0 b            10  
void at::native::(anonymous namespace)::multi_tensor...         0.00%       0.000us         0.00%       0.000us       0.000us     562.233us         0.26%     562.233us      56.223us           0 b           0 b           0 b           0 b            10  
void at::native::(anonymous namespace)::multi_tensor...         0.00%       0.000us         0.00%       0.000us       0.000us       1.168ms         0.53%       1.168ms     116.834us           0 b           0 b           0 b           0 b            10  
                                          ProfilerStep*         0.00%       0.000us         0.00%       0.000us       0.000us     374.005ms       169.92%     374.005ms     124.668ms           0 b           0 b           0 b           0 b             3  
                       Memcpy HtoD (Pageable -> Device)         0.00%       0.000us         0.00%       0.000us       0.000us       1.684ms         0.76%       1.684ms     280.589us           0 b           0 b           0 b           0 b             6  
                                                Scatter         0.19%       1.127ms         0.28%       1.652ms      45.888us       0.000us         0.00%       0.000us       0.000us           0 b           0 b           0 b           0 b            36  
                                            aten::chunk         0.02%      91.159us         0.09%     525.041us      14.584us       0.000us         0.00%       0.000us       0.000us           0 b           0 b           0 b           0 b            36  
                                            aten::split         0.03%     155.106us         0.07%     433.882us      12.052us       0.000us         0.00%       0.000us       0.000us           0 b           0 b           0 b           0 b            36  
                                           aten::narrow         0.02%     112.050us         0.05%     314.804us       7.495us       0.000us         0.00%       0.000us       0.000us           0 b           0 b           0 b           0 b            42  
                                            aten::slice         0.02%     143.493us         0.03%     202.754us       4.827us       0.000us         0.00%       0.000us       0.000us           0 b           0 b           0 b           0 b            42  
                                       aten::as_strided         0.44%       2.591ms         0.44%       2.591ms       1.407us       0.000us         0.00%       0.000us       0.000us           0 b           0 b           0 b           0 b          1842  
                                              aten::pad         0.12%     706.352us         1.70%       9.965ms      27.682us       0.000us         0.00%       5.922ms      16.451us           0 b           0 b       1.65 Gb           0 b           360  
                                 aten::reflection_pad2d         0.63%       3.691ms         1.58%       9.259ms      25.720us       5.922ms         2.69%       5.922ms      16.451us           0 b           0 b       1.65 Gb           0 b           360  
                                       cudaLaunchKernel        11.49%      67.485ms        11.49%      67.485ms       5.959us       0.000us         0.00%       0.000us       0.000us           0 b           0 b           0 b           0 b         11325  
                                   DataParallel.forward         0.00%       0.000us         0.00%       0.000us       0.000us     140.702ms        63.93%     140.702ms       3.908ms           0 b           0 b           0 b           0 b            36  
void at::native::(anonymous namespace)::reflection_p...         0.00%       0.000us         0.00%       0.000us       0.000us       5.922ms         2.69%       5.922ms      16.451us           0 b           0 b           0 b           0 b           360  
                                           aten::conv2d         0.22%       1.315ms         7.88%      46.289ms      95.245us       0.000us         0.00%      43.368ms      89.234us           0 b           0 b       1.94 Gb           0 b           486  
                                      aten::convolution         0.67%       3.915ms         8.22%      48.243ms      92.419us       0.000us         0.00%      46.869ms      89.787us           0 b           0 b       2.36 Gb           0 b           522  
                                     aten::_convolution         0.84%       4.919ms         7.55%      44.328ms      84.919us       0.000us         0.00%      46.869ms      89.787us           0 b           0 b       2.36 Gb           0 b           522  
                                        cudaEventRecord         0.41%       2.404ms         0.41%       2.404ms       1.590us       0.000us         0.00%       0.000us       0.000us           0 b           0 b           0 b           0 b          1512  
                                  cudaStreamIsCapturing         0.11%     651.484us         0.11%     651.484us       0.428us       0.000us         0.00%       0.000us       0.000us           0 b           0 b           0 b           0 b          1523  
                                  cudaStreamGetPriority         0.09%     528.100us         0.09%     528.100us       0.349us       0.000us         0.00%       0.000us       0.000us           0 b           0 b           0 b           0 b          1512  
                       cudaDeviceGetStreamPriorityRange         0.09%     505.471us         0.09%     505.471us       0.334us       0.000us         0.00%       0.000us       0.000us           0 b           0 b           0 b           0 b          1512  
                                    cudaPeekAtLastError         0.05%     270.047us         0.05%     270.047us       0.092us       0.000us         0.00%       0.000us       0.000us           0 b           0 b           0 b           0 b          2940  
                                    cudaLaunchKernelExC         0.64%       3.771ms         0.64%       3.771ms       4.587us       0.000us         0.00%       0.000us       0.000us           0 b           0 b           0 b           0 b           822  
sm80_xmma_fprop_implicit_gemm_indexed_wo_smem_tf32f3...         0.00%       0.000us         0.00%       0.000us       0.000us       1.065ms         0.48%       1.065ms      59.166us           0 b           0 b           0 b           0 b            18  
                                          aten::reshape         0.55%       3.204ms         1.14%       6.693ms       2.213us       0.000us         0.00%       0.000us       0.000us           0 b           0 b           0 b           0 b          3024  
                                             aten::view         1.20%       7.036ms         1.20%       7.036ms       1.437us       0.000us         0.00%       0.000us       0.000us           0 b           0 b           0 b           0 b          4896  
                                             aten::add_         1.55%       9.123ms         2.88%      16.906ms      10.099us       7.843ms         3.56%       7.843ms       4.685us           0 b           0 b           0 b           0 b          1674  
                                    aten::instance_norm         0.37%       2.195ms         6.71%      39.397ms      84.182us       0.000us         0.00%      11.982ms      25.602us           0 b           0 b       2.30 Gb           0 b           468  
                                       aten::batch_norm         0.15%     888.588us         5.79%      33.974ms      72.594us       0.000us         0.00%      11.982ms      25.602us           0 b           0 b       2.30 Gb           0 b           468  
                           aten::_batch_norm_impl_index         0.31%       1.834ms         5.64%      33.086ms      70.696us       0.000us         0.00%      11.982ms      25.602us           0 b           0 b       2.30 Gb           0 b           468  
                                aten::native_batch_norm         1.86%      10.944ms         4.91%      28.800ms      61.539us      11.965ms         5.44%      11.982ms      25.602us           0 b           0 b       2.30 Gb           0 b           468  
                                       aten::empty_like         0.55%       3.201ms         2.06%      12.099ms       7.483us       0.000us         0.00%       0.000us       0.000us           0 b           0 b       7.87 Gb           0 b          1617  
                                            aten::relu_         0.51%       3.020ms         1.08%       6.327ms      25.107us       0.000us         0.00%       1.557ms       6.179us           0 b           0 b           0 b           0 b           252  
                                       aten::clamp_min_         0.28%       1.617ms         0.56%       3.307ms      13.124us       1.557ms         0.71%       1.557ms       6.179us           0 b           0 b           0 b           0 b           252  
void at::native::vectorized_elementwise_kernel<4, at...         0.00%       0.000us         0.00%       0.000us       0.000us       1.557ms         0.71%       1.557ms       6.179us           0 b           0 b           0 b           0 b           252  
-------------------------------------------------------  ------------  ------------  ------------  ------------  ------------  ------------  ------------  ------------  ------------  ------------  ------------  ------------  ------------  ------------  
Self CPU time total: 587.107ms
Self CUDA time total: 220.101ms

